Workbook

Sheet Agents' Final Roster 0823-0829
A1: ACM | B1: Supervisor | C1: Last Name | D1: First Name | E1: Sunday | F1: Monday | G1: Tuesday | H1: Wednesday | I1: Thrusday | J1: Friday | K1: Saturday | L1: Attriton Date | M1: Comments | N1: Type | O1: Sun Hrs. | P1: Mon Hrs. | Q1: Tue Hrs. | R1: Wed Hrs. | S1: Thu Hrs. | T1: Fri Hrs. | U1: Sat Hrs. | V1: Scheduled Hrs. | W1: ACDID | X1: Agent´s Payroll Number | Y1: CCMSID | Z1: LOB | AA1: Secondary Skill | AB1: Supervisor´s Payroll Numer | AC1: ACM´s Payroll Number | AD1: NT Loguin | AE1: User #1 | AF1: WAHA desde | AG1: Telephone Number | AH1: DNI | AI1: CUIL | AJ1: TPARG Hire Date | AK1: Project Hire Date | AL1: Production Hire Date | AM1: Tenure | AN1: Site | AO1: Extensión | AP1: WAHA | AQ1: Horario Original
A2: Campero Juarez Maria Guadalupe | B2: Arias Juan José | C2: Bautista Boloña | D2: Luciana Florencia | E2: OFF | F2: 15:00 - 20:00 | G2: 15:00 - 20:00 | H2: 15:00 - 20:00 | I2: 15:00 - 20:00 | J2: 15:00 - 20:00 | K2: OFF | N2: PT | O2: 0 | P2: 5 | Q2: 5 | R2: 5 | S2: 5 | T2: 5 | U2: 0 | V2: 25 | W2: 89206 | X2: 87043 | Y2: 3409624 | Z2: CSV2 | AA2: CSV1 / CSV2 | AB2: 84825 | AC2: 74054 | AD2: bautistabolona.5 | AE2: VCTLUBAU | AF2: 43916 | AG2: 381-155811017 | AH2: 35517416 | AI2: 27355174161 | AJ2: 43668 | AK2: 43669 | AL2: 43678 | AM2: 397 | AN2: Campus Casino | AO2: 89953 | AP2: SI | AQ2: (Hs Orig 15:00 - 20:00 OFF Dom Sab)
A3: Campero Juarez Maria Guadalupe | B3: Arias Juan José | C3: Albornoz Perez | D3: Jose Ezequiel | E3: OFF | F3: 15:00 - 20:00 | G3: 15:00 - 20:00 | H3: 15:00 - 20:00 | I3: 15:00 - 20:00 | J3: 15:00 - 20:00 | K3: OFF | N3: PT | O3: 0 | P3: 5 | Q3: 5 | R3: 5 | S3: 5 | T3: 5 | U3: 0 | V3: 25 | W3: 648060 | X3: 88037 | Y3: 3553112 | Z3: DVH | AA3: CSV1 | AB3: 84825 | AC3: 74054 | AD3: albornozperez.5 | AE3: VCTJOALB | AF3: 43943 | AG3: 03814655139 | AH3: 39972625 | AI3: 20-39972625-6 | AJ3: 43942 | AK3: 43942 | AL3: 43943 | AM3: 128 | AN3: Campus Casino | AO3: 89999 | AP3: SI | AQ3: (Hs Orig 15:00 - 20:00 OFF Dom Sab)
A4: Campero Juarez Maria Guadalupe | B4: Arias Juan José | C4: Brito | D4: Jesus Exequiel | E4: OFF | F4: Approved OFF | G4: Approved OFF | H4: Approved OFF | I4: 15:00 - 21:00 | J4: 15:00 - 21:00 | K4: OFF | M4: Back From CAPA CSV2 a CSV3 08/11 - 08/26 (activo 08/27)(Hs Orig 15:00 - 21:00 OFF Dom Sab) | N4: PT | O4: 0 | P4: 0 | Q4: 0 | R4: 0 | S4: 6 | T4: 6 | U4: 0 | V4: 12 | W4: 89069 | X4: 82613 | Y4: 2313015 | Z4: CSV2 | AA4: CSV2 | AB4: 84825 | AC4: 74054 | AD4: brito.272 | AE4: VCTJEBRI | AF4: 43917 | AG4: 03865-15419891 | AH4: 37311054 | AI4: 20373110540 | AJ4: 42688 | AK4: 43369 | AL4: 43403 | AM4: 1365 | AN4: Campus Casino | AO4: 89924 | AP4: SI | AQ4: (Hs Orig 15:00 - 21:00 OFF Dom Sab)
A5: Campero Juarez Maria Guadalupe | B5: Arias Juan José | C5: Carabajal | D5: Priscila Daiana | E5: OFF | F5: 15:00 - 21:00 | G5: 15:00 - 21:00 | H5: 15:00 - 21:00 | I5: 15:00 - 21:00 | J5: 15:00 - 21:00 | K5: OFF | N5: PT | O5: 0 | P5: 6 | Q5: 6 | R5: 6 | S5: 6 | T5: 6 | U5: 0 | V5: 30 | W5: 89118 | X5: 86145 | Y5: 2358095 | Z5: CSV3 | AA5: CSV2 / CSV3 | AB5: 84825 | AC5: 74054 | AD5: carabajal.35 | AE5: VCTPRCAR | AF5: 43917 | AG5: 381-153508762 | AH5: 39141166 | AI5: 27391411668 | AJ5: 43437 | AK5: 43437 | AL5: 43448 | AM5: 626 | AN5: Campus Casino | AO5: 89925 | AP5: SI | AQ5: (Hs Orig 15:00 - 21:00 OFF Dom Sab)
A6: Campero Juarez Maria Guadalupe | B6: Arias Juan José | C6: Casares | D6: Diego Jesus | E6: OFF | F6: 15:00 - 21:00 | G6: 15:00 - 21:00 | H6: 15:00 - 21:00 | I6: 15:00 - 21:00 | J6: 15:00 - 21:00 | K6: OFF | N6: PT | O6: 0 | P6: 6 | Q6: 6 | R6: 6 | S6: 6 | T6: 6 | U6: 0 | V6: 30 | W6: 89061 | X6: 81099 | Y6: 1880623 | Z6: VIP | AA6: CSV2/HD / CSV3 / VIP | AB6: 84825 | AC6: 74054 | AD6: casares.15 | AE6: VCTDICAS | AF6: 43916 | AG6: 0381-154629051 | AH6: 37656704 | AI6: 20376567045 | AJ6: 42310 | AK6: 43327 | AL6: 43328 | AM6: 1737 | AN6: Campus Casino | AO6: 89926 | AP6: SI | AQ6: (Hs Orig 15:00 - 21:00 OFF Dom Sab)
A7: Campero Juarez Maria Guadalupe | B7: Arias Juan José | C7: Cisneros | D7: Roxana Natalia | E7: OFF | F7: 15:00 - 21:00 | G7: 15:00 - 21:00 | H7: 15:00 - 21:00 | I7: 15:00 - 21:00 | J7: 15:00 - 21:00 | K7: OFF | N7: PT | O7: 0 | P7: 6 | Q7: 6 | R7: 6 | S7: 6 | T7: 6 | U7: 0 | V7: 30 | W7: 89237 | X7: 87304 | Y7: 3462502 | Z7: Servicios web | AA7: CSV1 | AB7: 84825 | AC7: 74054 | AD7: cisneros.153 | AE7: VCTROCIS | AF7: 43915 | AG7: 3815811118 | AH7: 30759743 | AI7: 27307597433 | AJ7: 43703 | AK7: 43703 | AL7: 43713 | AM7: 363 | AN7: Campus Casino | AO7: 89875 | AP7: SI | AQ7: (Hs Orig 15:00 - 21:00 OFF Dom Sab)
A8: Campero Juarez Maria Guadalupe | B8: Arias Juan José | C8: Corbera | D8: Elena Beatriz | E8: OFF | F8: 15:00 - 21:00 | G8: 15:00 - 21:00 | H8: 15:00 - 21:00 | I8: 15:00 - 21:00 | J8: 15:00 - 21:00 | K8: OFF | N8: PT | O8: 0 | P8: 6 | Q8: 6 | R8: 6 | S8: 6 | T8: 6 | U8: 0 | V8: 30 | W8: 89227 | X8: 87314 | Y8: 3462518 | Z8: CSV2 | AA8: CSV1 / CSV2 | AB8: 84825 | AC8: 74054 | AD8: corbera.8 | AE8: VCTELCOR | AF8: 43916 | AG8: 3816363464 | AH8: 32200145 | AI8: 27322001458 | AJ8: 43703 | AK8: 43703 | AL8: 43713 | AM8: 363 | AN8: Campus Casino | AO8: 89928 | AP8: SI | AQ8: (Hs Orig 15:00 - 21:00 OFF Dom Sab)
A9: Perez Zitzke Agustina | B9: Vazquez Valladares Eduardo Alejandro | C9: Diaz | D9: Fernando Gabriel | E9: OFF | F9: 15:00 - 21:00 | G9: 15:00 - 21:00 | H9: 15:00 - 21:00 | I9: 15:00 - 21:00 | J9: 15:00 - 21:00 | K9: OFF | N9: PT | O9: 0 | P9: 6 | Q9: 6 | R9: 6 | S9: 6 | T9: 6 | U9: 0 | V9: 30 | W9: 89064 | X9: 85332 | Y9: 2811367 | Z9: CSV2 | AA9: CSV2 | AB9: #N/A | AC9: #N/A | AD9: diaz.1260 | AE9: VCTFEDIA | AF9: 44033 | AG9: 0381-156713498 | AH9: 36585224 | AI9: 20365852244 | AJ9: 43171 | AK9: 43327 | AL9: 43328 | AM9: 887 | AN9: Campus Casino | AO9: 89929 | AP9: On Site | AQ9: (Hs Orig 15:00 - 21:00 OFF Dom Sab)
A10: Campero Juarez Maria Guadalupe | B10: Arias Juan José | C10: Escobar | D10: Marcos Nahuel | E10: OFF | F10: Approved OFF | G10: Approved OFF | H10: Approved OFF | I10: 15:00 - 21:00 | J10: 15:00 - 21:00 | K10: OFF | M10: Back From CAPA CSV2 a CSV3 08/11 - 08/26 (activo 08/27)(Hs Orig 15:00 - 21:00 OFF Dom Sab) | N10: PT | O10: 0 | P10: 0 | Q10: 0 | R10: 0 | S10: 6 | T10: 6 | U10: 0 | V10: 12 | W10: 89121 | X10: 86155 | Y10: 2783079 | Z10: CSV2 | AA10: CSV1 / CSV2 | AB10: 84825 | AC10: 74054 | AD10: escobar.21 | AE10: VCTMAESC | AF10: 43916 | AG10: 381-156538022 | AH10: 38741741 | AI10: 23387417419 | AJ10: 43437 | AK10: 43437 | AL10: 43448 | AM10: 626 | AN10: Campus Casino | AO10: 89930 | AP10: SI | AQ10: (Hs Orig 15:00 - 21:00 OFF Dom Sab)
A11: Campero Juarez Maria Guadalupe | B11: Arias Juan José | C11: Juarez | D11: Carlos Luciano | E11: OFF | F11: Approved OFF | G11: Approved OFF | H11: Approved OFF | I11: Approved OFF | J11: Approved OFF | K11: OFF | M11: CAPA CSV3 a Vip 08/24 - 08/28 (activo 08/26)(Hs Orig 15:00 - 21:00 OFF Dom Sab) | N11: PT | O11: 0 | P11: 0 | Q11: 0 | R11: 0 | S11: 0 | T11: 0 | U11: 0 | V11: 0 | W11: 89125 | X11: 86141 | Y11: 3118306 | Z11: CSV3 | AA11: CSV2 / CSV3 | AB11: 84825 | AC11: 74054 | AD11: Juarez.286 | AE11: VCTCAJUA | AF11: 43945 | AG11: 381-155399372 | AH11: 40437730 | AI11: 20404377303 | AJ11: 43437 | AK11: 43437 | AL11: 43448 | AM11: 626 | AN11: Campus Casino | AO11: 89932 | AP11: SI | AQ11: (Hs Orig 15:00 - 21:00 OFF Dom Sab)
A12: Campero Juarez Maria Guadalupe | B12: Arias Juan José | C12: Muratore | D12: Daiana Gabriela | E12: OFF | F12: 15:00 - 21:00 | G12: 15:00 - 21:00 | H12: 15:00 - 21:00 | I12: 15:00 - 21:00 | J12: 15:00 - 21:00 | K12: OFF | N12: PT | O12: 0 | P12: 6 | Q12: 6 | R12: 6 | S12: 6 | T12: 6 | U12: 0 | V12: 30 | W12: 89053 | X12: 82401 | Y12: 1063468 | Z12: CSV2 | AA12: CSV2 | AB12: 84825 | AC12: 74054 | AD12: muratore.9 | AE12: VCTDAMUR | AF12: 43945 | AG12: 0381-153499565 | AH12: 37311904 | AI12: 27373119046 | AJ12: 42625 | AK12: 43327 | AL12: 43328 | AM12: 1427 | AN12: Campus Casino | AO12: 89933 | AP12: SI | AQ12: (Hs Orig 15:00 - 21:00 OFF Dom Sab)
A13: Campero Juarez Maria Guadalupe | B13: Arias Juan José | C13: Nunez | D13: Marcelo Nahuel | E13: OFF | F13: 15:00 - 21:00 | G13: 15:00 - 21:00 | H13: 15:00 - 21:00 | I13: 15:00 - 21:00 | J13: 15:00 - 21:00 | K13: OFF | N13: PT | O13: 0 | P13: 6 | Q13: 6 | R13: 6 | S13: 6 | T13: 6 | U13: 0 | V13: 30 | W13: 89164 | X13: 86296 | Y13: 3133293 | Z13: VIP | AA13: CSV2/CSV3 / VIP | AB13: 84825 | AC13: 74054 | AD13: nuez.128 | AE13: VCTMANUN | AF13: 43916 | AG13: 0381-156179830 | AH13: 42221286 | AI13: 20422212869 | AJ13: 43451 | AK13: 43451 | AL13: 43467 | AM13: 612 | AN13: Campus Casino | AO13: 89934 | AP13: SI | AQ13: (Hs Orig 15:00 - 21:00 OFF Dom Sab)
A14: Campero Juarez Maria Guadalupe | B14: Arias Juan José | C14: Ortiz | D14: Silvina Gabriela | E14: OFF | F14: 15:00 - 21:00 | G14: 15:00 - 21:00 | H14: 15:00 - 21:00 | I14: 15:00 - 21:00 | J14: 15:00 - 21:00 | K14: OFF | N14: PT | O14: 0 | P14: 6 | Q14: 6 | R14: 6 | S14: 6 | T14: 6 | U14: 0 | V14: 30 | W14: 89027 | X14: 85614 | Y14: 2873639 | Z14: CSV3 | AA14: CSV2/ CSV3 | AB14: 84825 | AC14: 74054 | AD14: ortiz.710 | AE14: VCTSIORT | AF14: 43917 | AG14: 0381-154061434 | AH14: 38115785 | AI14: 27381157852 | AJ14: 43227 | AK14: 43259 | AL14: 43262 | AM14: 832 | AN14: Campus Casino | AO14: 89935 | AP14: SI | AQ14: (Hs Orig 15:00 - 21:00 OFF Dom Sab)
A15: Campero Juarez Maria Guadalupe | B15: Arias Juan José | C15: Pockorny | D15: Tomás Agustín | E15: OFF | F15: 15:00 - 21:00 | G15: 15:00 - 21:00 | H15: 15:00 - 21:00 | I15: 15:00 - 21:00 | J15: 15:00 - 21:00 | K15: OFF | N15: PT | O15: 0 | P15: 6 | Q15: 6 | R15: 6 | S15: 6 | T15: 6 | U15: 0 | V15: 30 | W15: 89024 | X15: 85621 | Y15: 2873911 | Z15: CSV3 | AA15: CSV2/CSV3/ HD | AB15: 84825 | AC15: 74054 | AD15: pockorny.5 | AE15: VCTTOPOC | AF15: 43916 | AG15: 0381-156539796 | AH15: 38185380 | AI15: 20381853803 | AJ15: 43227 | AK15: 43259 | AL15: 43262 | AM15: 832 | AN15: Campus Casino | AO15: 89937 | AP15: SI | AQ15: (Hs Orig 15:00 - 21:00 OFF Dom Sab)
A16: Campero Juarez Maria Guadalupe | B16: Arias Juan José | C16: Yapura | D16: Cintia Elena del Valle | E16: OFF | F16: 15:00 - 21:00 | G16: 15:00 - 21:00 | H16: 15:00 - 21:00 | I16: 15:00 - 21:00 | J16: 15:00 - 21:00 | K16: OFF | N16: PT | O16: 0 | P16: 6 | Q16: 6 | R16: 6 | S16: 6 | T16: 6 | U16: 0 | V16: 30 | W16: 89059 | X16: 85474 | Y16: 2832262 | Z16: VIP | AA16: CSV2/HD / CSV3/ VIP | AB16: 84825 | AC16: 74054 | AD16: yapura.5 | AE16: VCTCIYAP | AF16: 43910 | AG16: 0381-155060573 | AH16: 40696111 | AI16: 27406961112 | AJ16: 43193 | AK16: 43327 | AL16: 43328 | AM16: 866 | AN16: Campus Casino | AO16: 89939 | AP16: SI | AQ16: (Hs Orig 15:00 - 21:00 OFF Dom Sab)
A17: Campero Juarez Maria Guadalupe | B17: Corbera Susana Sofía | C17: Alonso | D17: Facundo ismael | E17: OFF | F17: 15:00 - 21:00 | G17: 15:00 - 21:00 | H17: 15:00 - 21:00 | I17: 15:00 - 21:00 | J17: 15:00 - 21:00 | K17: OFF | N17: PT | O17: 0 | P17: 6 | Q17: 6 | R17: 6 | S17: 6 | T17: 6 | U17: 0 | V17: 30 | W17: 89313 | X17: 88174 | Y17: 3624184 | Z17: CSV2 | AA17: CSV2 | AB17: #N/A | AC17: 74054 | AD17: alonso.155 | AE17: VCTFAALO | AF17: 43917 | AH17: 42007693 | AI17: 20420076933 | AJ17: 43808 | AK17: 43808 | AL17: 43831 | AM17: 260 | AN17: Campus Casino | AO17: 89871 | AP17: SI | AQ17: (Hs Orig 15:00 - 21:00 OFF Dom Sab)
A18: Campero Juarez Maria Guadalupe | B18: Corbera Susana Sofía | C18: Alvarez Maziad | D18: Monica Carolina | E18: OFF | F18: 15:00 - 21:00 | G18: 15:00 - 21:00 | H18: 15:00 - 21:00 | I18: 15:00 - 21:00 | J18: 15:00 - 21:00 | K18: OFF | N18: PT | O18: 0 | P18: 6 | Q18: 6 | R18: 6 | S18: 6 | T18: 6 | U18: 0 | V18: 30 | W18: 89057 | X18: 83603 | Y18: 2523112 | Z18: CSV2 | AA18: CSV1 / CSV2 | AB18: #N/A | AC18: 74054 | AD18: alvarezmaziad.5 | AE18: VCTMOALV | AF18: 43917 | AG18: 0381-156802261 | AH18: 39145406 | AI18: 27391454065 | AJ18: 42891 | AK18: 43327 | AL18: 43328 | AM18: 1164 | AN18: Campus Casino | AO18: 89940 | AP18: SI | AQ18: (Hs Orig 15:00 - 21:00 OFF Dom Sab)
A19: Campero Juarez Maria Guadalupe | B19: Corbera Susana Sofía | C19: Azubel | D19: Solange | E19: OFF | F19: 15:00 - 21:00 | G19: 15:00 - 21:00 | H19: 15:00 - 21:00 | I19: 15:00 - 21:00 | J19: 15:00 - 21:00 | K19: OFF | N19: PT | O19: 0 | P19: 6 | Q19: 6 | R19: 6 | S19: 6 | T19: 6 | U19: 0 | V19: 30 | W19: 89225 | X19: 87316 | Y19: 1100247 | Z19: CSV3 | AA19: CSV2/ CSV3 | AB19: #N/A | AC19: 74054 | AD19: azubel.7 | AE19: VCTSOAZU | AF19: 43916 | AG19: 3814637258 | AH19: 35921500 | AI19: 27359215008 | AJ19: 43703 | AK19: 43703 | AL19: 43713 | AM19: 363 | AN19: Campus Casino | AO19: 89941 | AP19: SI | AQ19: (Hs Orig 15:00 - 21:00 OFF Dom Sab)
A20: Campero Juarez Maria Guadalupe | B20: Corbera Susana Sofía | C20: Cantos | D20: Horacio Nicolas | E20: OFF | F20: 15:00 - 21:00 | G20: 15:00 - 21:00 | H20: 15:00 - 21:00 | I20: 15:00 - 21:00 | J20: 15:00 - 21:00 | K20: OFF | N20: PT | O20: 0 | P20: 6 | Q20: 6 | R20: 6 | S20: 6 | T20: 6 | U20: 0 | V20: 30 | W20: 89236 | X20: 87308 | Y20: 3462509 | Z20: CSV3 | AA20: CSV2 / CSV3 | AB20: #N/A | AC20: 74054 | AD20: cantos.58 | AE20: VCTHOCAN | AF20: 43915 | AG20: 3814742874 | AH20: 41650790 | AI20: 20416507903 | AJ20: 43703 | AK20: 43703 | AL20: 43713 | AM20: 363 | AN20: Campus Casino | AO20: 89944 | AP20: SI | AQ20: (Hs Orig 15:00 - 21:00 OFF Dom Sab)
A21: Campero Juarez Maria Guadalupe | B21: Corbera Susana Sofía | C21: Castillo | D21: Angel Alberto | E21: OFF | F21: 15:00 - 21:00 | G21: 15:00 - 21:00 | H21: 15:00 - 21:00 | I21: 15:00 - 21:00 | J21: 15:00 - 21:00 | K21: OFF | N21: PT | O21: 0 | P21: 6 | Q21: 6 | R21: 6 | S21: 6 | T21: 6 | U21: 0 | V21: 30 | W21: 89104 | X21: 85278 | Y21: 2803851 | Z21: CSV3 | AA21: CSV2 / CSV3 | AB21: #N/A | AC21: 74054 | AD21: castillo.1268 | AE21: VCTANCAS | AF21: 43910 | AG21: 3816509596 | AH21: 37457052 | AI21: 20374570529 | AJ21: 43164 | AK21: 43409 | AL21: 43423 | AM21: 894 | AN21: Campus Casino | AO21: 89945 | AP21: SI | AQ21: (Hs Orig 15:00 - 21:00 OFF Dom Sab)
A22: Campero Juarez Maria Guadalupe | B22: Corbera Susana Sofía | C22: Chavarria Bevacqua | D22: Silvana Carolina | E22: OFF | F22: 15:00 - 20:00 | G22: 15:00 - 20:00 | H22: 15:00 - 20:00 | I22: 15:00 - 20:00 | J22: 15:00 - 20:00 | K22: OFF | N22: PT | O22: 0 | P22: 5 | Q22: 5 | R22: 5 | S22: 5 | T22: 5 | U22: 0 | V22: 25 | W22: 89207 | X22: 87045 | Y22: 3409666 | Z22: CSV2 | AA22: CSV1 / CSV2 | AB22: #N/A | AC22: 74054 | AD22: chavarriabevacqua.5 | AE22: VCTSICHA | AF22: 43916 | AG22: 381-156956998 | AH22: 35192091 | AI22: 27-35192091-8 | AJ22: 43668 | AK22: 43669 | AL22: 43678 | AM22: 397 | AN22: Campus Casino | AO22: 89887 | AP22: SI | AQ22: (Hs Orig 15:00 - 20:00 OFF Dom Sab)
A23: Campero Juarez Maria Guadalupe | B23: Corbera Susana Sofía | C23: Del Pino | D23: Agustin Alejandro | E23: OFF | F23: 16:00 - 21:00 | G23: 16:00 - 21:00 | H23: 16:00 - 21:00 | I23: 16:00 - 21:00 | J23: 16:00 - 21:00 | K23: OFF | N23: PT | O23: 0 | P23: 5 | Q23: 5 | R23: 5 | S23: 5 | T23: 5 | U23: 0 | V23: 25 | W23: 89211 | X23: 87057 | Y23: 3409641 | Z23: DVH | AA23: CSV1 | AB23: #N/A | AC23: 74054 | AD23: delpino.12 | AE23: VCTAGDEL | AF23: 43945 | AG23: 381-155438690 | AH23: 41495060 | AI23: 20414950605 | AJ23: 43668 | AK23: 43669 | AL23: 43678 | AM23: 397 | AN23: Campus Casino | AO23: 89876 | AP23: SI | AQ23: (Hs Orig 16:00 - 21:00 OFF Dom Sab)
A24: Campero Juarez Maria Guadalupe | B24: Corbera Susana Sofía | C24: Elias | D24: Mario Jorge | E24: OFF | F24: 15:00 - 21:00 | G24: 15:00 - 21:00 | H24: 15:00 - 21:00 | I24: 15:00 - 21:00 | J24: 15:00 - 21:00 | K24: OFF | N24: PT | O24: 0 | P24: 6 | Q24: 6 | R24: 6 | S24: 6 | T24: 6 | U24: 0 | V24: 30 | W24: 89119 | X24: 86154 | Y24: 3118300 | Z24: CSV2 | AA24: CSV2 | AB24: #N/A | AC24: 74054 | AD24: elias.112 | AE24: VCTMAELI | AF24: 43934 | AG24: 381-156987176 | AH24: 35822667 | AI24: 20358226672 | AJ24: 43437 | AK24: 43437 | AL24: 43448 | AM24: 626 | AN24: Campus Casino | AO24: 89946 | AP24: SI | AQ24: (Hs Orig 15:00 - 21:00 OFF Dom Sab)
A25: Campero Juarez Maria Guadalupe | B25: Corbera Susana Sofía | C25: Garcia | D25: Guillermo Eduardo | E25: OFF | F25: Approved OFF | G25: Approved OFF | H25: Approved OFF | I25: 15:00 - 21:00 | J25: 15:00 - 21:00 | K25: OFF | M25: Back From CAPA CSV2 a CSV3 08/11 - 08/26 (activo 08/27)(Hs Orig 15:00 - 21:00 OFF Dom Sab) | N25: PT | O25: 0 | P25: 0 | Q25: 0 | R25: 0 | S25: 6 | T25: 6 | U25: 0 | V25: 12 | W25: 89001 | X25: 83911 | Y25: 2657668 | Z25: CSV2 | AA25: CSV2 | AB25: #N/A | AC25: 74054 | AD25: garcia.3872 | AE25: VCTGUGAR | AF25: 43921 | AG25: 0381-156358727 | AH25: 37455215 | AI25: 20374552156 | AJ25: 43010 | AK25: 43259 | AL25: 43262 | AM25: 1047 | AN25: Campus Casino | AO25: 89947 | AP25: SI | AQ25: (Hs Orig 15:00 - 21:00 OFF Dom Sab)
A26: Campero Juarez Maria Guadalupe | B26: Corbera Susana Sofía | C26: Gjugum | D26: Sofia Denise | E26: OFF | F26: 15:00 - 21:00 | G26: 15:00 - 21:00 | H26: 15:00 - 21:00 | I26: 15:00 - 21:00 | J26: 15:00 - 21:00 | K26: OFF | N26: PT | O26: 0 | P26: 6 | Q26: 6 | R26: 6 | S26: 6 | T26: 6 | U26: 0 | V26: 30 | W26: 89229 | X26: 87310 | Y26: 3462512 | Z26: CSV3 | AA26: CSV2 / CSV3 | AB26: #N/A | AC26: 74054 | AD26: gjugum.7 | AE26: VCTSOGJU | AF26: 43917 | AG26: 3816313769 | AH26: 40532665 | AI26: 27405326650 | AJ26: 43703 | AK26: 43703 | AL26: 43713 | AM26: 363 | AN26: Campus Casino | AO26: 89948 | AP26: SI | AQ26: (Hs Orig 15:00 - 21:00 OFF Dom Sab)
A27: Campero Juarez Maria Guadalupe | B27: Corbera Susana Sofía | C27: Laitán Landro | D27: Gimena María | E27: OFF | F27: 15:00 - 21:00 | G27: 15:00 - 21:00 | H27: 15:00 - 21:00 | I27: 15:00 - 21:00 | J27: 15:00 - 21:00 | K27: OFF | N27: PT | O27: 0 | P27: 6 | Q27: 6 | R27: 6 | S27: 6 | T27: 6 | U27: 0 | V27: 30 | W27: 89056 | X27: 85310 | Y27: 2811372 | Z27: HD | AA27: CSV2/CSV3/HD | AB27: #N/A | AC27: 74054 | AD27: laitnlandro.5 | AE27: VCTGILAI | AF27: 43917 | AG27: 0381-156311579 | AH27: 36865396 | AI27: 27368653964 | AJ27: 43171 | AK27: 43327 | AL27: 43328 | AM27: 887 | AN27: Campus Casino | AO27: 89949 | AP27: SI | AQ27: (Hs Orig 15:00 - 21:00 OFF Dom Sab)
A28: Campero Juarez Maria Guadalupe | B28: Corbera Susana Sofía | C28: Martinez Teseyra | D28: Mayra Belen | E28: OFF | F28: 16:00 - 21:00 | G28: 16:00 - 21:00 | H28: 16:00 - 21:00 | I28: 16:00 - 21:00 | J28: 16:00 - 21:00 | K28: OFF | N28: PT | O28: 0 | P28: 5 | Q28: 5 | R28: 5 | S28: 5 | T28: 5 | U28: 0 | V28: 25 | W28: 89215 | X28: 87060 | Y28: 3409628 | Z28: CSV2 | AA28: CSV1 / CSV2 | AB28: #N/A | AC28: 74054 | AD28: martinezteseyra.5 | AE28: VCTBEMAR | AF28: 43934 | AG28: 3876-15401588 | AH28: 36129883 | AI28: 27361298832 | AJ28: 43668 | AK28: 43669 | AL28: 43678 | AM28: 397 | AN28: Campus Casino | AO28: 89961 | AP28: SI | AQ28: (Hs Orig 16:00 - 21:00 OFF Dom Sab)
A29: Campero Juarez Maria Guadalupe | B29: Corbera Susana Sofía | C29: Medina | D29: Leyla Maria | E29: OFF | F29: Approved OFF | G29: Approved OFF | H29: Approved OFF | I29: Approved OFF | J29: Approved OFF | K29: OFF | M29: CAPA CSV3 a Vip 08/24 - 08/28 (activo 08/26)(Hs Orig 15:00 - 21:00 OFF Dom Sab) | N29: PT | O29: 0 | P29: 0 | Q29: 0 | R29: 0 | S29: 0 | T29: 0 | U29: 0 | V29: 0 | W29: 89241 | X29: 87306 | Y29: 1729885 | Z29: HD | AA29: CSV2 / HD/ CSV3 | AB29: #N/A | AC29: 74054 | AD29: medina.894 | AE29: VCTLEMED | AF29: 43915 | AG29: 3813545684 | AH29: 36584345 | AI29: 27365843452 | AJ29: 43703 | AK29: 43703 | AL29: 43713 | AM29: 363 | AN29: Campus Casino | AO29: 89950 | AP29: SI | AQ29: (Hs Orig 15:00 - 21:00 OFF Dom Sab)
A30: Campero Juarez Maria Guadalupe | B30: Corbera Susana Sofía | C30: Nasif | D30: Mara Belen | E30: OFF | F30: 15:00 - 21:00 | G30: 15:00 - 21:00 | H30: 15:00 - 21:00 | I30: 15:00 - 21:00 | J30: 15:00 - 21:00 | K30: OFF | N30: PT | O30: 0 | P30: 6 | Q30: 6 | R30: 6 | S30: 6 | T30: 6 | U30: 0 | V30: 30 | W30: 89242 | X30: 87300 | Y30: 3462489 | Z30: DVH | AA30: CSV1 | AB30: #N/A | AC30: 74054 | AD30: nasif.8 | AE30: VCTMANAS | AG30: 3854161581 | AH30: 35251517 | AI30: 27352515170 | AJ30: 43703 | AK30: 43703 | AL30: 43713 | AM30: 363 | AN30: Campus Casino | AP30: NO | AQ30: (Hs Orig 15:00 - 21:00 OFF Dom Sab)
A31: Campero Juarez Maria Guadalupe | B31: Corbera Susana Sofía | C31: Ricci | D31: Marcos Jose | E31: OFF | F31: Approved OFF | G31: Approved OFF | H31: Approved OFF | I31: Approved OFF | J31: Approved OFF | K31: OFF | M31: CAPA CSV3 a Vip 08/24 - 08/28 (activo 08/26)(Hs Orig 15:00 - 21:00 OFF Dom Sab) | N31: PT | O31: 0 | P31: 0 | Q31: 0 | R31: 0 | S31: 0 | T31: 0 | U31: 0 | V31: 0 | W31: 89168 | X31: 86288 | Y31: 3133272 | Z31: CSV3 | AA31: CSV2 / HD/ CSV3 | AB31: #N/A | AC31: 74054 | AD31: ricci.57 | AE31: VCTMARIC | AF31: 43916 | AG31: 0381-154498587 | AH31: 36550805 | AI31: 20365508055 | AJ31: 43451 | AK31: 43451 | AL31: 43467 | AM31: 612 | AN31: Campus Casino | AO31: 89951 | AP31: SI | AQ31: (Hs Orig 15:00 - 21:00 OFF Dom Sab)
A32: Campero Juarez Maria Guadalupe | B32: Corbera Susana Sofía | C32: Ruiz Barrionuevo | D32: Isabella Catalina | E32: OFF | F32: 16:00 - 21:00 | G32: 16:00 - 21:00 | H32: 16:00 - 21:00 | I32: 16:00 - 21:00 | J32: 16:00 - 21:00 | K32: OFF | N32: PT | O32: 0 | P32: 5 | Q32: 5 | R32: 5 | S32: 5 | T32: 5 | U32: 0 | V32: 25 | W32: 89218 | X32: 87054 | Y32: 3409729 | Z32: CSV2 | AA32: CSV1 / CSV2 | AB32: #N/A | AC32: 74054 | AD32: ruizbarrionuevo.6 | AE32: VCTISRUI | AF32: 43915 | AG32: 381-153676323 | AH32: 42664926 | AI32: 27426649263 | AJ32: 43668 | AK32: 43669 | AL32: 43678 | AM32: 397 | AN32: Campus Casino | AO32: 89981 | AP32: SI | AQ32: (Hs Orig 16:00 - 21:00 OFF Dom Sab)
A33: Campero Juarez Maria Guadalupe | B33: Criado Esteban | C33: Amicone | D33: Julieta | E33: OFF | F33: 15:00 - 21:00 | G33: 15:00 - 21:00 | H33: 15:00 - 21:00 | I33: 15:00 - 21:00 | J33: 15:00 - 21:00 | K33: OFF | N33: PT | O33: 0 | P33: 6 | Q33: 6 | R33: 6 | S33: 6 | T33: 6 | U33: 0 | V33: 30 | W33: 648384 | X33: 86201 | Y33: 3120478 | Z33: CSV1 | AA33: CSV1 | AB33: 85154 | AC33: 74054 | AD33: amicone.9 | AE33: VCTJUAMI | AF33: 43969 | AG33: 381 432 4959 | AH33: 42007271 | AI33: 27420072711 | AJ33: 43437 | AK33: 43962 | AL33: 43969 | AM33: 626 | AN33: Campus Casino | AO33: 648326 | AP33: SI | AQ33: (Hs Orig 15:00 - 21:00 OFF Dom Sab)
A34: Campero Juarez Maria Guadalupe | B34: Criado Esteban | C34: Arias | D34: Ivan Santiago | E34: OFF | F34: 15:00 - 21:00 | G34: 15:00 - 21:00 | H34: 15:00 - 21:00 | I34: 15:00 - 21:00 | J34: 15:00 - 21:00 | K34: OFF | N34: PT | O34: 0 | P34: 6 | Q34: 6 | R34: 6 | S34: 6 | T34: 6 | U34: 0 | V34: 30 | W34: 648392 | X34: 86212 | Y34: 3119977 | Z34: DVH | AA34: CSV1 | AB34: 85154 | AC34: 74054 | AD34: arias.197 | AE34: VCTIVARI | AF34: 43969 | AG34: 381 364 1513 | AH34: 36839830 | AI34: 20368398307 | AJ34: 43437 | AK34: 43962 | AL34: 43969 | AM34: 626 | AN34: Campus Casino | AO34: 648331 | AP34: SI | AQ34: (Hs Orig 15:00 - 21:00 OFF Dom Sab)
A35: Campero Juarez Maria Guadalupe | B35: Criado Esteban | C35: Bernard | D35: Mariano | E35: OFF | F35: 15:00 - 21:00 | G35: 15:00 - 21:00 | H35: 15:00 - 21:00 | I35: 15:00 - 21:00 | J35: 15:00 - 21:00 | K35: OFF | N35: PT | O35: 0 | P35: 6 | Q35: 6 | R35: 6 | S35: 6 | T35: 6 | U35: 0 | V35: 30 | W35: 648378 | X35: 86585 | Y35: 3290393 | Z35: CSV1 | AA35: CSV1 | AB35: 85154 | AC35: 74054 | AD35: bernard.212 | AE35: VCTMABER | AF35: 43969 | AG35: 3816761743 | AH35: 37457894 | AI35: 20374578945 | AJ35: 43594 | AK35: 43962 | AL35: 43969 | AM35: 470 | AN35: Campus Casino | AO35: 648321 | AP35: SI | AQ35: (Hs Orig 15:00 - 21:00 OFF Dom Sab)
A36: Campero Juarez Maria Guadalupe | B36: Criado Esteban | C36: Blacut | D36: Carolina Concepcion | E36: OFF | F36: 13:00 - 19:00 | G36: 13:00 - 19:00 | H36: 13:00 - 19:00 | I36: 13:00 - 19:00 | J36: 13:00 - 19:00 | K36: OFF | N36: PT | O36: 0 | P36: 6 | Q36: 6 | R36: 6 | S36: 6 | T36: 6 | U36: 0 | V36: 30 | W36: 648379 | X36: 64114 | Y36: 433384 | Z36: CSV1 | AA36: CSV1 | AB36: 85154 | AC36: 74054 | AD36: blacut.5 | AE36: VCTCABLA | AF36: 43969 | AG36: 3814360935 | AH36: 22989370 | AI36: 27229893705 | AJ36: 39937 | AK36: 43962 | AL36: 43969 | AM36: 4075 | AN36: Campus Casino | AO36: 648322 | AP36: SI | AQ36: (Hs Orig 13:00 - 19:00 OFF Dom Sab)
A37: Campero Juarez Maria Guadalupe | B37: Criado Esteban | C37: Chico | D37: Jessica Liliana | E37: OFF | F37: 15:00 - 21:00 | G37: 15:00 - 21:00 | H37: 15:00 - 21:00 | I37: 15:00 - 21:00 | J37: 15:00 - 21:00 | K37: OFF | N37: PT | O37: 0 | P37: 6 | Q37: 6 | R37: 6 | S37: 6 | T37: 6 | U37: 0 | V37: 30 | W37: 648381 | X37: 82194 | Y37: 2178609 | Z37: CSV1 | AA37: CSV1 | AB37: 85154 | AC37: 74054 | AD37: chico.47 | AE37: VCTJECHI | AF37: 43969 | AG37: 4330399 / 155782351 | AH37: 36584697 | AI37: 27365846974 | AJ37: 42580 | AK37: 43962 | AL37: 43969 | AM37: 1470 | AN37: Campus Casino | AO37: 648324 | AP37: SI | AQ37: (Hs Orig 15:00 - 21:00 OFF Dom Sab)
A38: Campero Juarez Maria Guadalupe | B38: Criado Esteban | C38: Ferraro | D38: David Franco Ramón | E38: OFF | F38: 15:00 - 21:00 | G38: 15:00 - 21:00 | H38: 15:00 - 21:00 | I38: 15:00 - 21:00 | J38: 15:00 - 21:00 | K38: OFF | N38: PT | O38: 0 | P38: 6 | Q38: 6 | R38: 6 | S38: 6 | T38: 6 | U38: 0 | V38: 30 | W38: 648382 | X38: 87912 | Y38: 3526348 | Z38: CSV1 | AA38: CSV1 | AB38: 85154 | AC38: 74054 | AD38: ferraro.26 | AE38: VCTDAFER | AF38: 43969 | AG38: 381 153907269 | AH38: 37310000 | AI38: 20373100006 | AJ38: 43745 | AK38: 43962 | AL38: 43969 | AM38: 322 | AN38: Campus Casino | AO38: 648325 | AP38: SI | AQ38: (Hs Orig 15:00 - 21:00 OFF Dom Sab)
A39: Campero Juarez Maria Guadalupe | B39: Criado Esteban | C39: Jandar | D39: Fabio Nicolás | E39: OFF | F39: 15:00 - 21:00 | G39: 15:00 - 21:00 | H39: 15:00 - 21:00 | I39: 15:00 - 21:00 | J39: 15:00 - 21:00 | K39: OFF | N39: PT | O39: 0 | P39: 6 | Q39: 6 | R39: 6 | S39: 6 | T39: 6 | U39: 0 | V39: 30 | W39: 648390 | X39: 83918 | Y39: 2657804 | Z39: CSV1 | AA39: CSV1 | AB39: 85154 | AC39: 74054 | AD39: jandar.8 | AE39: VCTFAJAN | AF39: 43969 | AG39: 0381-154180132 | AH39: 39481787 | AI39: 20394817873 | AJ39: 43010 | AK39: 43962 | AL39: 43969 | AM39: 1047 | AN39: Campus Casino | AO39: 648330 | AP39: SI | AQ39: (Hs Orig 15:00 - 21:00 OFF Dom Sab)
A40: Campero Juarez Maria Guadalupe | B40: Criado Esteban | C40: Jerez | D40: María Celeste | E40: OFF | F40: 16:00 - 21:00 | G40: 16:00 - 21:00 | H40: 16:00 - 21:00 | I40: 16:00 - 21:00 | J40: 16:00 - 21:00 | K40: OFF | N40: PT | O40: 0 | P40: 5 | Q40: 5 | R40: 5 | S40: 5 | T40: 5 | U40: 0 | V40: 25 | W40: 648385 | X40: 81571 | Y40: 1988450 | Z40: DVH | AA40: CSV1 | AB40: 85154 | AC40: 74054 | AD40: jerez.37 | AE40: VCTMAJER | AF40: 43969 | AG40: 0381 155585231 | AH40: 34764648 | AI40: 27347646488 | AJ40: 42429 | AK40: 43962 | AL40: 43969 | AM40: 1619 | AN40: Campus Casino | AO40: 648337 | AP40: SI | AQ40: (Hs Orig 16:00 - 21:00 OFF Dom Sab)
...

Sheet Sups' Final Roster 0823-0829
A1: ACM | B1: Supervisor | C1: Sunday | D1: Monday | E1: Tuesday | F1: Wednesday | G1: Thrusday | H1: Friday | I1: Saturday | J1: Legajo | K1: CCMSID
A2: Campero Juarez Maria Guadalupe | B2: Arias Juan José | C2: OFF | D2: 12:00 - 21:00 | E2: 12:00 - 21:00 | F2: 12:00 - 21:00 | G2: 12:00 - 21:00 | H2: 12:00 - 21:00 | I2: OFF | J2: 84825 | K2: 2770365
A3: Campero Juarez Maria Guadalupe | B3: Corbera Susana Sofía | C3: OFF | D3: 12:00 - 21:00 | E3: 12:00 - 21:00 | F3: 12:00 - 21:00 | G3: 12:00 - 21:00 | H3: 12:00 - 21:00 | I3: OFF | J3: 81043 | K3: 1880608
A4: Campero Juarez Maria Guadalupe | B4: Podazza Villagra Daniel Matias | C4: OFF | D4: 12:00 - 21:00 | E4: 12:00 - 21:00 | F4: 12:00 - 21:00 | G4: 12:00 - 21:00 | H4: 12:00 - 21:00 | I4: OFF | J4: 80740 | K4: 1793255
A5: Campero Juarez Maria Guadalupe | B5: Gregoratti Juan Carlos | C5: OFF | D5: 12:00 - 21:00 | E5: 12:00 - 21:00 | F5: 12:00 - 21:00 | G5: 12:00 - 21:00 | H5: 12:00 - 21:00 | I5: OFF | J5: 79688 | K5: 1453697
A6: Pérez Zitzke Agustina | B6: Vazquez Valladares Eduardo Alejandro | C6: OFF | D6: 12:00 - 21:00 | E6: 12:00 - 21:00 | F6: 12:00 - 21:00 | G6: 12:00 - 21:00 | H6: 12:00 - 21:00 | I6: OFF | J6: 77681 | K6: 1077981
A7: Pérez Zitzke Agustina | B7: Ramallo Jose Emanuel | C7: OFF | D7: 12:00 - 21:00 | E7: 12:00 - 21:00 | F7: 12:00 - 21:00 | G7: 12:00 - 21:00 | H7: 12:00 - 21:00 | I7: OFF | J7: 79479 | K7: 1407265
A8: Campero Juarez Maria Guadalupe | B8: Criado Esteban | C8: OFF | D8: 12:00 - 21:00 | E8: 12:00 - 21:00 | F8: 12:00 - 21:00 | G8: 12:00 - 21:00 | H8: 12:00 - 21:00 | I8: OFF | J8: 85154 | K8: 1815266
A9: Ortiz Jose María | B9: Diaz Jesica Luciana | C9: OFF | D9: 07:30 - 16:30 | E9: 07:30 - 16:30 | F9: 07:30 - 16:30 | G9: 07:30 - 16:30 | H9: 07:30 - 16:30 | I9: OFF | J9: 66977 | K9: 500642
A10: Pérez Zitzke Agustina | B10: Villa Aleman Alejandro Roberto | C10: OFF | D10: 08:00 - 17:00 | E10: 08:00 - 17:00 | F10: 08:00 - 17:00 | G10: 08:00 - 17:00 | H10: 08:00 - 17:00 | I10: OFF | J10: 81755 | K10: 2052783
A11: Ortiz Jose María | B11: Brandan Ernesto Alejandro | C11: OFF | D11: 08:00 - 17:00 | E11: 08:00 - 17:00 | F11: 08:00 - 17:00 | G11: 08:00 - 17:00 | H11: 08:00 - 17:00 | I11: OFF | J11: 74323 | K11: 595902
A12: Ortiz Jose María | B12: Britos Fernando José | C12: OFF | D12: 08:00 - 17:00 | E12: 08:00 - 17:00 | F12: 08:00 - 17:00 | G12: 08:00 - 17:00 | H12: 08:00 - 17:00 | I12: OFF | J12: 70271 | K12: 490014
A13: Ortiz Jose María | B13: Esquivel Pavan Pamela Sol | C13: OFF | D13: 08:00 - 17:00 | E13: 08:00 - 17:00 | F13: 08:00 - 17:00 | G13: 08:00 - 17:00 | H13: 08:00 - 17:00 | I13: OFF | J13: 78667 | K13: 1244026
... A20: Ortiz Jose María | B20: Silva Gabriel Alberto | C20: OFF | D20: 08:00 - 17:00 | E20: 08:00 - 17:00 | F20: 08:00 - 17:00 | G20: 08:00 - 17:00 | H20: 08:00 - 17:00 | I20: OFF | J20: 84144 | K20: 2714348

Sheet ACMs' Final Roster 0823-0829
A1: CCM | B1: ACM | C1: Sunday | D1: Monday | E1: Tuesday | F1: Wednesday | G1: Thrusday | H1: Friday | I1: Saturday | J1: Legajo | K1: CCMSID
A2: Décima Romina Soledad | B2: Ortiz Jose María | C2: OFF | D2: 09:00 - 18:00 | E2: 09:00 - 18:00 | F2: 09:00 - 18:00 | G2: 09:00 - 18:00 | H2: 09:00 - 18:00 | I2: OFF | J2: 64118 | K2: 433569
A3: Décima Romina Soledad | B3: Campero Juarez Maria Guadalupe | C3: OFF | D3: 11:00 - 20:00 | E3: 11:00 - 20:00 | F3: 11:00 - 20:00 | G3: 11:00 - 20:00 | H3: 11:00 - 20:00 | I3: OFF | J3: 74054 | K3: 590259
A4: Décima Romina Soledad | B4: Pérez Zitzke Agustina | C4: OFF | D4: 09:00 - 18:00 | E4: 09:00 - 18:00 | F4: 09:00 - 18:00 | G4: 09:00 - 18:00 | H4: 09:00 - 18:00 | I4: OFF | J4: 59438 | K4: 433173

Sheet Ratios
A1: RATIO Prisma
A3: ACM | B3: Supervisor | C3: Supervisores | D3: Share | H3: ACM | I3: Supervisor | J3: Agentes | K3: Share
A4: Ortiz Jose María | B4: Diaz Jesica Luciana | C4: 20 | D4: 0.06116208 | H4: Ortiz Jose María | I4: Brandan Ernesto Alejandro | J4: 21 | K4: 0.10144928
B5: Brandan Ernesto Alejandro | C5: 21 | D5: 0.064220183 | I5: Esquivel Pavan Pamela Sol | J5: 21 | K5: 0.10144928
B6: Esquivel Pavan Pamela Sol | C6: 21 | D6: 0.064220183 | I6: Diaz Jesica Luciana | J6: 20 | K6: 0.096618357
B7: Gerez Andrea Soledad | C7: 19 | D7: 0.058103976 | I7: Gerez Andrea Soledad | J7: 19 | K7: 0.09178744
B8: Britos Fernando José | C8: 16 | D8: 0.048929664 | I8: Britos Fernando José | J8: 16 | K8: 0.077294686
B9: Silva Gabriel Alberto | C9: 9 | D9: 0.027522936 | H9: Ortiz Jose María Total | J9: 97 | K9: 0.46859903
A10: Ortiz Jose María Total | C10: 106 | D10: 0.32415902 | H10: Campero Juarez Maria Guadalupe | I10: Podazza Villagra Daniel Matias | J10: 19 | K10: 0.09178744
A11: Campero Juarez Maria Guadalupe | B11: Arias Juan José | C11: 18 | D11: 0.055045872 | I11: Corbera Susana Sofía | J11: 19 | K11: 0.09178744
B12: Podazza Villagra Daniel Matias | C12: 19 | D12: 0.058103976 | I12: Arias Juan José | J12: 18 | K12: 0.086956522
B13: Gregoratti Juan Carlos | C13: 17 | D13: 0.051987768 | I13: Gregoratti Juan Carlos | J13: 17 | K13: 0.082125604
B14: Corbera Susana Sofía | C14: 19 | D14: 0.058103976 | H14: Campero Juarez Maria Guadalupe Total | J14: 73 | K14: 0.352657
B15: Criado Esteban | C15: 20 | D15: 0.06116208 | H15: Perez Zitzke Agustina | I15: Villa Aleman Alejandro Roberto | J15: 21 | K15: 0.10144928
B16: Bachur Karim | C16: 14 | D16: 0.042813456 | I16: Vazquez Valladares Eduardo Alejandro | J16: 16 | K16: 0.077294686
B17: Mendoza Norma Mercedes | C17: 13 | D17: 0.039755352 | H17: Perez Zitzke Agustina Total | J17: 37 | K17: 0.17874396
A18: Campero Juarez Maria Guadalupe Total | C18: 120 | D18: 0.36697248 | H18: Grand Total | J18: 207 | K18: 1
A19: Perez Zitzke Agustina | B19: Vazquez Valladares Eduardo Alejandro | C19: 16 | D19: 0.048929664
B20: Villa Aleman Alejandro Roberto | C20: 21 | D20: 0.064220183
B21: Grimaldi Agustina Sofía | C21: 17 | D21: 0.051987768
B22: Ramallo Jose Emanuel | C22: 19 | D22: 0.058103976
B23: Palomino Juan Pablo | C23: 19 | D23: 0.058103976
B24: Albornoz Miguel | C24: 9 | D24: 0.027522936
A25: Perez Zitzke Agustina Total | C25: 101 | D25: 0.3088685
A26: Grand Total | C26: 327 | D26: 1

Sheet Agents
A1: ACM | B1: Supervisor | C1: Last Name | D1: First Name | E1: Sunday | F1: Monday | G1: Tuesday | H1: Wednesday | I1: Thrusday | J1: Friday | K1: Saturday | L1: Attriton Date | M1: Comments | N1: Type | O1: Sun Hrs. | P1: Mon Hrs. | Q1: Tue Hrs. | R1: Wed Hrs. | S1: Thu Hrs. | T1: Fri Hrs. | U1: Sat Hrs. | V1: Scheduled Hrs. | W1: ACDID | X1: Agent´s Payroll Number | Y1: CCMSID | Z1: LOB | AA1: Secondary Skill | AB1: Supervisor´s Payroll Numer | AC1: ACM´s Payroll Number | AD1: NT Loguin | AE1: User #1 | AF1: User #2 | AG1: Telephone Number | AH1: DNI | AI1: CUIL | AJ1: TPARG Hire Date | AK1: Project Hire Date | AL1: Production Hire Date | AM1: Tenure | AN1: Site | AO1: Set Skill Programado | AP1: LOA
A2: ='Agents'' Final Roster 0823-0829'!A2 -> Campero Juarez Maria Guadalupe | B2: ='Agents'' Final Roster 0823-0829'!B2 -> Arias Juan José | C2: ='Agents'' Final Roster 0823-0829'!C2 -> Bautista Boloña | D2: ='Agents'' Final Roster 0823-0829'!D2 -> Luciana Florencia | Z2: ='Agents'' Final Roster 0823-0829'!Z2 -> CSV2
A3: ='Agents'' Final Roster 0823-0829'!A3 -> Campero Juarez Maria Guadalupe | B3: ='Agents'' Final Roster 0823-0829'!B3 -> Arias Juan José | C3: ='Agents'' Final Roster 0823-0829'!C3 -> Albornoz Perez | D3: ='Agents'' Final Roster 0823-0829'!D3 -> Jose Ezequiel | Z3: ='Agents'' Final Roster 0823-0829'!Z3 -> DVH
A4: ='Agents'' Final Roster 0823-0829'!A4 -> Campero Juarez Maria Guadalupe | B4: ='Agents'' Final Roster 0823-0829'!B4 -> Arias Juan José | C4: ='Agents'' Final Roster 0823-0829'!C4 -> Brito | D4: ='Agents'' Final Roster 0823-0829'!D4 -> Jesus Exequiel | Z4: ='Agents'' Final Roster 0823-0829'!Z4 -> CSV2
A5: ='Agents'' Final Roster 0823-0829'!A5 -> Campero Juarez Maria Guadalupe | B5: ='Agents'' Final Roster 0823-0829'!B5 -> Arias Juan José | C5: ='Agents'' Final Roster 0823-0829'!C5 -> Carabajal | D5: ='Agents'' Final Roster 0823-0829'!D5 -> Priscila Daiana | Z5: ='Agents'' Final Roster 0823-0829'!Z5 -> CSV3
A6: ='Agents'' Final Roster 0823-0829'!A6 -> Campero Juarez Maria Guadalupe | B6: ='Agents'' Final Roster 0823-0829'!B6 -> Arias Juan José | C6: ='Agents'' Final Roster 0823-0829'!C6 -> Casares | D6: ='Agents'' Final Roster 0823-0829'!D6 -> Diego Jesus | Z6: ='Agents'' Final Roster 0823-0829'!Z6 -> VIP
A7: ='Agents'' Final Roster 0823-0829'!A7 -> Campero Juarez Maria Guadalupe | B7: ='Agents'' Final Roster 0823-0829'!B7 -> Arias Juan José | C7: ='Agents'' Final Roster 0823-0829'!C7 -> Cisneros | D7: ='Agents'' Final Roster 0823-0829'!D7 -> Roxana Natalia | Z7: ='Agents'' Final Roster 0823-0829'!Z7 -> Servicios web
A8: ='Agents'' Final Roster 0823-0829'!A8 -> Campero Juarez Maria Guadalupe | B8: ='Agents'' Final Roster 0823-0829'!B8 -> Arias Juan José | C8: ='Agents'' Final Roster 0823-0829'!C8 -> Corbera | D8: ='Agents'' Final Roster 0823-0829'!D8 -> Elena Beatriz | Z8: ='Agents'' Final Roster 0823-0829'!Z8 -> CSV2
A9: ='Agents'' Final Roster 0823-0829'!A9 -> Perez Zitzke Agustina | B9: ='Agents'' Final Roster 0823-0829'!B9 -> Vazquez Valladares Eduardo Alejandro | C9: ='Agents'' Final Roster 0823-0829'!C9 -> Diaz | D9: ='Agents'' Final Roster 0823-0829'!D9 -> Fernando Gabriel | Z9: ='Agents'' Final Roster 0823-0829'!Z9 -> CSV2
A10: ='Agents'' Final Roster 0823-0829'!A10 -> Campero Juarez Maria Guadalupe | B10: ='Agents'' Final Roster 0823-0829'!B10 -> Arias Juan José | C10: ='Agents'' Final Roster 0823-0829'!C10 -> Escobar | D10: ='Agents'' Final Roster 0823-0829'!D10 -> Marcos Nahuel | Z10: ='Agents'' Final Roster 0823-0829'!Z10 -> CSV2
A11: ='Agents'' Final Roster 0823-0829'!A11 -> Campero Juarez Maria Guadalupe | B11: ='Agents'' Final Roster 0823-0829'!B11 -> Arias Juan José | C11: ='Agents'' Final Roster 0823-0829'!C11 -> Juarez | D11: ='Agents'' Final Roster 0823-0829'!D11 -> Carlos Luciano | Z11: ='Agents'' Final Roster 0823-0829'!Z11 -> CSV3
A12: ='Agents'' Final Roster 0823-0829'!A12 -> Campero Juarez Maria Guadalupe | B12: ='Agents'' Final Roster 0823-0829'!B12 -> Arias Juan José | C12: ='Agents'' Final Roster 0823-0829'!C12 -> Muratore | D12: ='Agents'' Final Roster 0823-0829'!D12 -> Daiana Gabriela | Z12: ='Agents'' Final Roster 0823-0829'!Z12 -> CSV2
A13: ='Agents'' Final Roster 0823-0829'!A13 -> Campero Juarez Maria Guadalupe | B13: ='Agents'' Final Roster 0823-0829'!B13 -> Arias Juan José | C13: ='Agents'' Final Roster 0823-0829'!C13 -> Nunez | D13: ='Agents'' Final Roster 0823-0829'!D13 -> Marcelo Nahuel | Z13: ='Agents'' Final Roster 0823-0829'!Z13 -> VIP
... A184: ='Agents'' Final Roster 0823-0829'!A184 -> Perez Zitzke Agustina | B184: ='Agents'' Final Roster 0823-0829'!B184 -> Villa Aleman Alejandro Roberto | C184: ='Agents'' Final Roster 0823-0829'!C184 -> Teves | D184: ='Agents'' Final Roster 0823-0829'!D184 -> Emiliano Gabriel | Z184: ='Agents'' Final Roster 0823-0829'!Z184 -> DVH
A185: ='Agents'' Final Roster 0823-0829'!#REF! -> #REF! | B185: ='Agents'' Final Roster 0823-0829'!#REF! -> #REF! | C185: ='Agents'' Final Roster 0823-0829'!#REF! -> #REF! | D185: ='Agents'' Final Roster 0823-0829'!#REF! -> #REF! | Z185: ='Agents'' Final Roster 0823-0829'!#REF! -> #REF!
A186: ='Agents'' Final Roster 0823-0829'!#REF! -> #REF! | B186: ='Agents'' Final Roster 0823-0829'!#REF! -> #REF! | C186: ='Agents'' Final Roster 0823-0829'!#REF! -> #REF! | D186: ='Agents'' Final Roster 0823-0829'!#REF! -> #REF! | Z186: ='Agents'' Final Roster 0823-0829'!#REF! -> #REF!
A187: ='Agents'' Final Roster 0823-0829'!#REF! -> #REF! | B187: ='Agents'' Final Roster 0823-0829'!#REF! -> #REF! | C187: ='Agents'' Final Roster 0823-0829'!#REF! -> #REF! | D187: ='Agents'' Final Roster 0823-0829'!#REF! -> #REF! | Z187: ='Agents'' Final Roster 0823-0829'!#REF! -> #REF!
A188: ='Agents'' Final Roster 0823-0829'!#REF! -> #REF! | B188: ='Agents'' Final Roster 0823-0829'!#REF! -> #REF! | C188: ='Agents'' Final Roster 0823-0829'!#REF! -> #REF! | D188: ='Agents'' Final Roster 0823-0829'!#REF! -> #REF! | Z188: ='Agents'' Final Roster 0823-0829'!#REF! -> #REF!
A189: ='Agents'' Final Roster 0823-0829'!#REF! -> #REF! | B189: ='Agents'' Final Roster 0823-0829'!#REF! -> #REF! | C189: ='Agents'' Final Roster 0823-0829'!#REF! -> #REF! | D189: ='Agents'' Final Roster 0823-0829'!#REF! -> #REF! | Z189: ='Agents'' Final Roster 0823-0829'!#REF! -> #REF!
A190: ='Agents'' Final Roster 0823-0829'!#REF! -> #REF! | B190: ='Agents'' Final Roster 0823-0829'!#REF! -> #REF! | C190: ='Agents'' Final Roster 0823-0829'!#REF! -> #REF! | D190: ='Agents'' Final Roster 0823-0829'!#REF! -> #REF! | Z190: ='Agents'' Final Roster 0823-0829'!#REF! -> #REF!
A191: ='Agents'' Final Roster 0823-0829'!#REF! -> #REF! | B191: ='Agents'' Final Roster 0823-0829'!#REF! -> #REF! | C191: ='Agents'' Final Roster 0823-0829'!#REF! -> #REF! | D191: ='Agents'' Final Roster 0823-0829'!#REF! -> #REF! | Z191: ='Agents'' Final Roster 0823-0829'!#REF! -> #REF!
A192: ='Agents'' Final Roster 0823-0829'!#REF! -> #REF! | B192: ='Agents'' Final Roster 0823-0829'!#REF! -> #REF! | C192: ='Agents'' Final Roster 0823-0829'!#REF! -> #REF! | D192: ='Agents'' Final Roster 0823-0829'!#REF! -> #REF! | Z192: ='Agents'' Final Roster 0823-0829'!#REF! -> #REF!
A193: ='Agents'' Final Roster 0823-0829'!#REF! -> #REF! | B193: ='Agents'' Final Roster 0823-0829'!#REF! -> #REF! | C193: ='Agents'' Final Roster 0823-0829'!#REF! -> #REF! | D193: ='Agents'' Final Roster 0823-0829'!#REF! -> #REF! | Z193: ='Agents'' Final Roster 0823-0829'!#REF! -> #REF!
A194: ='Agents'' Final Roster 0823-0829'!#REF! -> #REF! | B194: ='Agents'' Final Roster 0823-0829'!#REF! -> #REF! | C194: ='Agents'' Final Roster 0823-0829'!#REF! -> #REF! | D194: ='Agents'' Final Roster 0823-0829'!#REF! -> #REF! | Z194: ='Agents'' Final Roster 0823-0829'!#REF! -> #REF!
A195: ='Agents'' Final Roster 0823-0829'!#REF! -> #REF! | B195: ='Agents'' Final Roster 0823-0829'!#REF! -> #REF! | C195: ='Agents'' Final Roster 0823-0829'!#REF! -> #REF! | D195: ='Agents'' Final Roster 0823-0829'!#REF! -> #REF! | Z195: ='Agents'' Final Roster 0823-0829'!#REF! -> #REF!
A196: ='Agents'' Final Roster 0823-0829'!#REF! -> #REF! | B196: ='Agents'' Final Roster 0823-0829'!#REF! -> #REF! | C196: ='Agents'' Final Roster 0823-0829'!#REF! -> #REF! | D196: ='Agents'' Final Roster 0823-0829'!#REF! -> #REF! | Z196: ='Agents'' Final Roster 0823-0829'!#REF! -> #REF!
... A239: ='Agents'' Final Roster 0823-0829'!#REF! -> #REF! | B239: ='Agents'' Final Roster 0823-0829'!#REF! -> #REF! | C239: ='Agents'' Final Roster 0823-0829'!#REF! -> #REF! | D239: ='Agents'' Final Roster 0823-0829'!#REF! -> #REF! | Z239: ='Agents'' Final Roster 0823-0829'!#REF! -> #REF!
A240: ='Agents'' Final Roster 0823-0829'!A185 -> Campero Juarez Maria Guadalupe | B240: ='Agents'' Final Roster 0823-0829'!B185 -> Arias Juan José | C240: ='Agents'' Final Roster 0823-0829'!C185 -> Ale | D240: ='Agents'' Final Roster 0823-0829'!D185 -> Rocío Agustina | Z240: ='Agents'' Final Roster 0823-0829'!Z185 -> Servicios web
A241: ='Agents'' Final Roster 0823-0829'!A186 -> Campero Juarez Maria Guadalupe | B241: ='Agents'' Final Roster 0823-0829'!B186 -> Arias Juan José | C241: ='Agents'' Final Roster 0823-0829'!C186 -> Aragón | D241: ='Agents'' Final Roster 0823-0829'!D186 -> Maria Celeste | Z241: ='Agents'' Final Roster 0823-0829'!Z186 -> Compras Referidas
A242: ='Agents'' Final Roster 0823-0829'!A187 -> Campero Juarez Maria Guadalupe | B242: ='Agents'' Final Roster 0823-0829'!B187 -> Arias Juan José | C242: ='Agents'' Final Roster 0823-0829'!C187 -> Cejas | D242: ='Agents'' Final Roster 0823-0829'!D187 -> Ignacio Martin | Z242: ='Agents'' Final Roster 0823-0829'!Z187 -> Compras Referidas
A243: ='Agents'' Final Roster 0823-0829'!A188 -> Campero Juarez Maria Guadalupe | B243: ='Agents'' Final Roster 0823-0829'!B188 -> Arias Juan José | C243: ='Agents'' Final Roster 0823-0829'!C188 -> Quiroga | D243: ='Agents'' Final Roster 0823-0829'!D188 -> Marianella Stefania | Z243: ='Agents'' Final Roster 0823-0829'!Z188 -> Servicios web
A244: ='Agents'' Final Roster 0823-0829'!A189 -> Campero Juarez Maria Guadalupe | B244: ='Agents'' Final Roster 0823-0829'!B189 -> Corbera Susana Sofía | C244: ='Agents'' Final Roster 0823-0829'!C189 -> Pomo | D244: ='Agents'' Final Roster 0823-0829'!D189 -> Daniel Nicolas | Z244: ='Agents'' Final Roster 0823-0829'!Z189 -> Compras Referidas
A245: ='Agents'' Final Roster 0823-0829'!A190 -> Campero Juarez Maria Guadalupe | B245: ='Agents'' Final Roster 0823-0829'!B190 -> Corbera Susana Sofía | C245: ='Agents'' Final Roster 0823-0829'!C190 -> Soto | D245: ='Agents'' Final Roster 0823-0829'!D190 -> Fatima Belen | Z245: ='Agents'' Final Roster 0823-0829'!Z190 -> CSV2
A246: ='Agents'' Final Roster 0823-0829'!A191 -> Campero Juarez Maria Guadalupe | B246: ='Agents'' Final Roster 0823-0829'!B191 -> Criado Esteban | C246: ='Agents'' Final Roster 0823-0829'!C191 -> Formoselle | D246: ='Agents'' Final Roster 0823-0829'!D191 -> Ivana Veronica | Z246: ='Agents'' Final Roster 0823-0829'!Z191 -> Servicios web
A247: ='Agents'' Final Roster 0823-0829'!A192 -> Campero Juarez Maria Guadalupe | B247: ='Agents'' Final Roster 0823-0829'!B192 -> Criado Esteban | C247: ='Agents'' Final Roster 0823-0829'!C192 -> Giolito | D247: ='Agents'' Final Roster 0823-0829'!D192 -> Maira Elizabeth | Z247: ='Agents'' Final Roster 0823-0829'!Z192 -> DVH
A248: ='Agents'' Final Roster 0823-0829'!A193 -> Campero Juarez Maria Guadalupe | B248: ='Agents'' Final Roster 0823-0829'!B193 -> Criado Esteban | C248: ='Agents'' Final Roster 0823-0829'!C193 -> López | D248: ='Agents'' Final Roster 0823-0829'!D193 -> Matias Gonzalo | Z248: ='Agents'' Final Roster 0823-0829'!Z193 -> Compras Referidas
A249: ='Agents'' Final Roster 0823-0829'!A194 -> Campero Juarez Maria Guadalupe | B249: ='Agents'' Final Roster 0823-0829'!B194 -> Criado Esteban | C249: ='Agents'' Final Roster 0823-0829'!C194 -> Palavecino | D249: ='Agents'' Final Roster 0823-0829'!D194 -> Pablo Mauricio | Z249: ='Agents'' Final Roster 0823-0829'!Z194 -> Compras Referidas
A250: ='Agents'' Final Roster 0823-0829'!A195 -> Perez Zitzke Agustina | B250: ='Agents'' Final Roster 0823-0829'!B195 -> Vazquez Valladares Eduardo Alejandro | C250: ='Agents'' Final Roster 0823-0829'!C195 -> Coronel | D250: ='Agents'' Final Roster 0823-0829'!D195 -> José Benjamín | Z250: ='Agents'' Final Roster 0823-0829'!Z195 -> Servicios web
A251: ='Agents'' Final Roster 0823-0829'!A196 -> Campero Juarez Maria Guadalupe | B251: ='Agents'' Final Roster 0823-0829'!B196 -> Gregoratti Juan Carlos | C251: ='Agents'' Final Roster 0823-0829'!C196 -> Ferroni | D251: ='Agents'' Final Roster 0823-0829'!D196 -> Carlos Agustin | Z251: ='Agents'' Final Roster 0823-0829'!Z196 -> Compras Referidas
... A306: ='Agents'' Final Roster 0823-0829'!A251 -> Perez Zitzke Agustina | B306: ='Agents'' Final Roster 0823-0829'!B251 -> Ramallo Jose Emanuel | C306: ='Agents'' Final Roster 0823-0829'!C251 -> Prado | D306: ='Agents'' Final Roster 0823-0829'!D251 -> Maria de los Angeles | Z306: ='Agents'' Final Roster 0823-0829'!Z251 -> Compras Referidas
...

Sheet Sups
A1: ACM | B1: Supervisor | C1: Sunday | D1: Monday | E1: Tuesday | F1: Wednesday | G1: Thrusday | H1: Friday | I1: Saturday | J1: Legajo | K1: CCMSID | L1: Legajo Telecom | M1: LOB
A2: ='Sups'' Final Roster 0823-0829'!A2 -> Campero Juarez Maria Guadalupe | B2: ='Sups'' Final Roster 0823-0829'!B2 -> Arias Juan José
A3: ='Sups'' Final Roster 0823-0829'!A3 -> Campero Juarez Maria Guadalupe | B3: ='Sups'' Final Roster 0823-0829'!B3 -> Corbera Susana Sofía
A4: ='Sups'' Final Roster 0823-0829'!A4 -> Campero Juarez Maria Guadalupe | B4: ='Sups'' Final Roster 0823-0829'!B4 -> Podazza Villagra Daniel Matias
A5: ='Sups'' Final Roster 0823-0829'!A5 -> Campero Juarez Maria Guadalupe | B5: ='Sups'' Final Roster 0823-0829'!B5 -> Gregoratti Juan Carlos
A6: ='Sups'' Final Roster 0823-0829'!A6 -> Pérez Zitzke Agustina | B6: ='Sups'' Final Roster 0823-0829'!B6 -> Vazquez Valladares Eduardo Alejandro
A7: ='Sups'' Final Roster 0823-0829'!A7 -> Pérez Zitzke Agustina | B7: ='Sups'' Final Roster 0823-0829'!B7 -> Ramallo Jose Emanuel
A8: ='Sups'' Final Roster 0823-0829'!A8 -> Campero Juarez Maria Guadalupe | B8: ='Sups'' Final Roster 0823-0829'!B8 -> Criado Esteban
A9: ='Sups'' Final Roster 0823-0829'!A10 -> Pérez Zitzke Agustina | B9: ='Sups'' Final Roster 0823-0829'!B10 -> Villa Aleman Alejandro Roberto
A10: ='Sups'' Final Roster 0823-0829'!A11 -> Ortiz Jose María | B10: ='Sups'' Final Roster 0823-0829'!B11 -> Brandan Ernesto Alejandro
A11: ='Sups'' Final Roster 0823-0829'!A12 -> Ortiz Jose María | B11: ='Sups'' Final Roster 0823-0829'!B12 -> Britos Fernando José
A12: ='Sups'' Final Roster 0823-0829'!#REF! -> #REF! | B12: ='Sups'' Final Roster 0823-0829'!#REF! -> #REF!
A13: ='Sups'' Final Roster 0823-0829'!#REF! -> #REF! | B13: ='Sups'' Final Roster 0823-0829'!#REF! -> #REF!
A14: ='Sups'' Final Roster 0823-0829'!#REF! -> #REF! | B14: ='Sups'' Final Roster 0823-0829'!#REF! -> #REF!
A15: ='Sups'' Final Roster 0823-0829'!#REF! -> #REF! | B15: ='Sups'' Final Roster 0823-0829'!#REF! -> #REF!
A16: ='Sups'' Final Roster 0823-0829'!#REF! -> #REF! | B16: ='Sups'' Final Roster 0823-0829'!#REF! -> #REF!
A17: ='Sups'' Final Roster 0823-0829'!#REF! -> #REF! | B17: ='Sups'' Final Roster 0823-0829'!#REF! -> #REF!
A18: ='Sups'' Final Roster 0823-0829'!#REF! -> #REF! | B18: ='Sups'' Final Roster 0823-0829'!#REF! -> #REF!
A19: ='Sups'' Final Roster 0823-0829'!#REF! -> #REF! | B19: ='Sups'' Final Roster 0823-0829'!#REF! -> #REF!
A20: ='Sups'' Final Roster 0823-0829'!#REF! -> #REF! | B20: ='Sups'' Final Roster 0823-0829'!#REF! -> #REF!
A21: ='Sups'' Final Roster 0823-0829'!#REF! -> #REF! | B21: ='Sups'' Final Roster 0823-0829'!#REF! -> #REF!
A22: ='Sups'' Final Roster 0823-0829'!#REF! -> #REF! | B22: ='Sups'' Final Roster 0823-0829'!#REF! -> #REF!
A23: ='Sups'' Final Roster 0823-0829'!#REF! -> #REF! | B23: ='Sups'' Final Roster 0823-0829'!#REF! -> #REF!
A24: ='Sups'' Final Roster 0823-0829'!A13 -> Ortiz Jose María | B24: ='Sups'' Final Roster 0823-0829'!B13 -> Esquivel Pavan Pamela Sol
A25: ='Sups'' Final Roster 0823-0829'!A14 -> Ortiz Jose María | B25: ='Sups'' Final Roster 0823-0829'!B14 -> Gerez Andrea Soledad
A26: ='Sups'' Final Roster 0823-0829'!#REF! -> #REF! | B26: ='Sups'' Final Roster 0823-0829'!#REF! -> #REF!
A27: ='Sups'' Final Roster 0823-0829'!#REF! -> #REF! | B27: ='Sups'' Final Roster 0823-0829'!#REF! -> #REF!
A28: ='Sups'' Final Roster 0823-0829'!#REF! -> #REF! | B28: ='Sups'' Final Roster 0823-0829'!#REF! -> #REF!
A29: ='Sups'' Final Roster 0823-0829'!#REF! -> #REF! | B29: ='Sups'' Final Roster 0823-0829'!#REF! -> #REF!
A30: ='Sups'' Final Roster 0823-0829'!#REF! -> #REF! | B30: ='Sups'' Final Roster 0823-0829'!#REF! -> #REF!
A31: ='Sups'' Final Roster 0823-0829'!#REF! -> #REF! | B31: ='Sups'' Final Roster 0823-0829'!#REF! -> #REF!
A32: ='Sups'' Final Roster 0823-0829'!#REF! -> #REF! | B32: ='Sups'' Final Roster 0823-0829'!#REF! -> #REF!
A33: ='Sups'' Final Roster 0823-0829'!#REF! -> #REF! | B33: ='Sups'' Final Roster 0823-0829'!#REF! -> #REF!
A34: ='Sups'' Final Roster 0823-0829'!#REF! -> #REF! | B34: ='Sups'' Final Roster 0823-0829'!#REF! -> #REF!
A35: ='Sups'' Final Roster 0823-0829'!#REF! -> #REF! | B35: ='Sups'' Final Roster 0823-0829'!#REF! -> #REF!
A36: ='Sups'' Final Roster 0823-0829'!#REF! -> #REF! | B36: ='Sups'' Final Roster 0823-0829'!#REF! -> #REF!
A37: ='Sups'' Final Roster 0823-0829'!#REF! -> #REF! | B37: ='Sups'' Final Roster 0823-0829'!#REF! -> #REF!
... A43: ='Sups'' Final Roster 0823-0829'!#REF! -> #REF! | B43: ='Sups'' Final Roster 0823-0829'!#REF! -> #REF!
A44: ='Sups'' Final Roster 0823-0829'!A15 -> Pérez Zitzke Agustina | B44: ='Sups'' Final Roster 0823-0829'!B15 -> Grimaldi Agustina Sofía
A45: ='Sups'' Final Roster 0823-0829'!A16 -> Pérez Zitzke Agustina | B45: ='Sups'' Final Roster 0823-0829'!B16 -> Palomino Juan Pablo
...

Sheet Resumen
G1: h
B2: Lob | C2: Nomina | D2: LOAs | E2: %
B3: Front | C3: =+COUNTIF(Agents!$Z$2:$Z$149,Resumen!B3) -> 0 | D3: =+SUMIF(Agents!$Z$2:$Z$149,Resumen!B3,Agents!$AP$2:$AP$149) -> 0 | E3: =D3/C3 -> #DIV/0!
B4: Retención Móvil | C4: =+COUNTIF(Agents!$Z$2:$Z$149,Resumen!B4) -> 0 | D4: =+SUMIF(Agents!$Z$2:$Z$149,Resumen!B4,Agents!$AP$2:$AP$149) -> 0 | E4: =D4/C4 -> #DIV/0!
B5: Downselling | C5: =+COUNTIF(Agents!$Z$2:$Z$149,Resumen!B5) -> 0 | D5: =+SUMIF(Agents!$Z$2:$Z$149,Resumen!B5,Agents!$AP$2:$AP$149) -> 0 | E5: =D5/C5 -> #DIV/0!
B6: Retención Red Preferida | C6: =+COUNTIF(Agents!$Z$2:$Z$149,Resumen!B6) -> 0 | D6: =+SUMIF(Agents!$Z$2:$Z$149,Resumen!B6,Agents!$AP$2:$AP$149) -> 0 | E6: =D6/C6 -> #DIV/0!
B7: Total | C7: =SUM(C3:C6) -> 0 | D7: =SUM(D3:D6) -> 0 | E7: =D7/C7 -> #DIV/0!
B9: Front
C11: Sunday | D11: Monday | E11: Tuesday | F11: Wednesday | G11: Thrusday | H11: Friday | I11: Saturday
B12: HC Total Inbound | C12: =+COUNTIF(Agents!$Z$2:$Z$149,Resumen!B3) -> 0 | D12: =+C12 -> 0 | E12: =+D12 -> 0 | F12: =+E12 -> 0 | G12: =+F12 -> 0 | H12: =+G12 -> 0 | I12: =+H12 -> 0
B13: Approved OFF | C13: =+COUNTIFS(Agents!E$2:E$149,Resumen!$B13,Agents!$Z$2:$Z$149,Resumen!$B$3) -> 0 | D13: =+COUNTIFS(Agents!F$2:F$149,Resumen!$B13,Agents!$Z$2:$Z$149,Resumen!$B$3) -> 0 | E13: =+COUNTIFS(Agents!G$2:G$149,Resumen!$B13,Agents!$Z$2:$Z$149,Resumen!$B$3) -> 0 | F13: =+COUNTIFS(Agents!H$2:H$149,Resumen!$B13,Agents!$Z$2:$Z$149,Resumen!$B$3) -> 0 | G13: =+COUNTIFS(Agents!I$2:I$149,Resumen!$B13,Agents!$Z$2:$Z$149,Resumen!$B$3) -> 0 | H13: =+COUNTIFS(Agents!J$2:J$149,Resumen!$B13,Agents!$Z$2:$Z$149,Resumen!$B$3) -> 0 | I13: =+COUNTIFS(Agents!K$2:K$149,Resumen!$B13,Agents!$Z$2:$Z$149,Resumen!$B$3) -> 0
B14: LOA | C14: =+COUNTIFS(Agents!E$2:E$149,Resumen!$B14,Agents!$Z$2:$Z$149,Resumen!$B$3) -> 0 | D14: =+COUNTIFS(Agents!F$2:F$149,Resumen!$B14,Agents!$Z$2:$Z$149,Resumen!$B$3) -> 0 | E14: =+COUNTIFS(Agents!G$2:G$149,Resumen!$B14,Agents!$Z$2:$Z$149,Resumen!$B$3) -> 0 | F14: =+COUNTIFS(Agents!H$2:H$149,Resumen!$B14,Agents!$Z$2:$Z$149,Resumen!$B$3) -> 0 | G14: =+COUNTIFS(Agents!I$2:I$149,Resumen!$B14,Agents!$Z$2:$Z$149,Resumen!$B$3) -> 0 | H14: =+COUNTIFS(Agents!J$2:J$149,Resumen!$B14,Agents!$Z$2:$Z$149,Resumen!$B$3) -> 0 | I14: =+COUNTIFS(Agents!K$2:K$149,Resumen!$B14,Agents!$Z$2:$Z$149,Resumen!$B$3) -> 0
B15: OFF | C15: =+COUNTIFS(Agents!E$2:E$149,Resumen!$B15,Agents!$Z$2:$Z$149,Resumen!$B$3) -> 0 | D15: =+COUNTIFS(Agents!F$2:F$149,Resumen!$B15,Agents!$Z$2:$Z$149,Resumen!$B$3) -> 0 | E15: =+COUNTIFS(Agents!G$2:G$149,Resumen!$B15,Agents!$Z$2:$Z$149,Resumen!$B$3) -> 0 | F15: =+COUNTIFS(Agents!H$2:H$149,Resumen!$B15,Agents!$Z$2:$Z$149,Resumen!$B$3) -> 0 | G15: =+COUNTIFS(Agents!I$2:I$149,Resumen!$B15,Agents!$Z$2:$Z$149,Resumen!$B$3) -> 0 | H15: =+COUNTIFS(Agents!J$2:J$149,Resumen!$B15,Agents!$Z$2:$Z$149,Resumen!$B$3) -> 0 | I15: =+COUNTIFS(Agents!K$2:K$149,Resumen!$B15,Agents!$Z$2:$Z$149,Resumen!$B$3) -> 0
B16: Study Day | C16: =+COUNTIFS(Agents!E$2:E$149,Resumen!$B16,Agents!$Z$2:$Z$149,Resumen!$B$3) -> 0 | D16: =+COUNTIFS(Agents!F$2:F$149,Resumen!$B16,Agents!$Z$2:$Z$149,Resumen!$B$3) -> 0 | E16: =+COUNTIFS(Agents!G$2:G$149,Resumen!$B16,Agents!$Z$2:$Z$149,Resumen!$B$3) -> 0 | F16: =+COUNTIFS(Agents!H$2:H$149,Resumen!$B16,Agents!$Z$2:$Z$149,Resumen!$B$3) -> 0 | G16: =+COUNTIFS(Agents!I$2:I$149,Resumen!$B16,Agents!$Z$2:$Z$149,Resumen!$B$3) -> 0 | H16: =+COUNTIFS(Agents!J$2:J$149,Resumen!$B16,Agents!$Z$2:$Z$149,Resumen!$B$3) -> 0 | I16: =+COUNTIFS(Agents!K$2:K$149,Resumen!$B16,Agents!$Z$2:$Z$149,Resumen!$B$3) -> 0
B17: VAC | C17: =+COUNTIFS(Agents!E$2:E$149,Resumen!$B17,Agents!$Z$2:$Z$149,Resumen!$B$3) -> 0 | D17: =+COUNTIFS(Agents!F$2:F$149,Resumen!$B17,Agents!$Z$2:$Z$149,Resumen!$B$3) -> 0 | E17: =+COUNTIFS(Agents!G$2:G$149,Resumen!$B17,Agents!$Z$2:$Z$149,Resumen!$B$3) -> 0 | F17: =+COUNTIFS(Agents!H$2:H$149,Resumen!$B17,Agents!$Z$2:$Z$149,Resumen!$B$3) -> 0 | G17: =+COUNTIFS(Agents!I$2:I$149,Resumen!$B17,Agents!$Z$2:$Z$149,Resumen!$B$3) -> 0 | H17: =+COUNTIFS(Agents!J$2:J$149,Resumen!$B17,Agents!$Z$2:$Z$149,Resumen!$B$3) -> 0 | I17: =+COUNTIFS(Agents!K$2:K$149,Resumen!$B17,Agents!$Z$2:$Z$149,Resumen!$B$3) -> 0
B18: SUS | C18: =+COUNTIFS(Agents!E$2:E$149,Resumen!$B18,Agents!$Z$2:$Z$149,Resumen!$B$3) -> 0 | D18: =+COUNTIFS(Agents!F$2:F$149,Resumen!$B18,Agents!$Z$2:$Z$149,Resumen!$B$3) -> 0 | E18: =+COUNTIFS(Agents!G$2:G$149,Resumen!$B18,Agents!$Z$2:$Z$149,Resumen!$B$3) -> 0 | F18: =+COUNTIFS(Agents!H$2:H$149,Resumen!$B18,Agents!$Z$2:$Z$149,Resumen!$B$3) -> 0 | G18: =+COUNTIFS(Agents!I$2:I$149,Resumen!$B18,Agents!$Z$2:$Z$149,Resumen!$B$3) -> 0 | H18: =+COUNTIFS(Agents!J$2:J$149,Resumen!$B18,Agents!$Z$2:$Z$149,Resumen!$B$3) -> 0 | I18: =+COUNTIFS(Agents!K$2:K$149,Resumen!$B18,Agents!$Z$2:$Z$149,Resumen!$B$3) -> 0
B19: HC Bis | C19: =+C12-SUM(C13:C18) -> 0 | D19: =+D12-SUM(D13:D18) -> 0 | E19: =+E12-SUM(E13:E18) -> 0 | F19: =+F12-SUM(F13:F18) -> 0 | G19: =+G12-SUM(G13:G18) -> 0 | H19: =+H12-SUM(H13:H18) -> 0 | I19: =+I12-SUM(I13:I18) -> 0
B20: HC Total Inbound Neto | C20: =+C12-C15-C13 -> 0 | D20: =+D12-D15-D13 -> 0 | E20: =+E12-E15-E13 -> 0 | F20: =+F12-F15-F13 -> 0 | G20: =+G12-G15-G13 -> 0 | H20: =+H12-H15-H13 -> 0 | I20: =+I12-I15-I13 -> 0
C22: =+C11 -> Sunday | D22: =+D11 -> Monday | E22: =+E11 -> Tuesday | F22: =+F11 -> Wednesday | G22: =+G11 -> Thrusday | H22: =+H11 -> Friday | I22: =+I11 -> Saturday
B23: Hs, Total Inbound | C23: =+SUMIF(Agents!$Z$2:$Z$149,Resumen!$B$3,Agents!O$2:O$149) -> 0 | D23: =+SUMIF(Agents!$Z$2:$Z$149,Resumen!$B$3,Agents!P$2:P$149) -> 0 | E23: =+SUMIF(Agents!$Z$2:$Z$149,Resumen!$B$3,Agents!Q$2:Q$149) -> 0 | F23: =+SUMIF(Agents!$Z$2:$Z$149,Resumen!$B$3,Agents!R$2:R$149) -> 0 | G23: =+SUMIF(Agents!$Z$2:$Z$149,Resumen!$B$3,Agents!S$2:S$149) -> 0 | H23: =+SUMIF(Agents!$Z$2:$Z$149,Resumen!$B$3,Agents!T$2:T$149) -> 0 | I23: =+SUMIF(Agents!$Z$2:$Z$149,Resumen!$B$3,Agents!U$2:U$149) -> 0
B24: Shift Avg. | C24: =IFERROR(C23/C19,0) -> 0 | D24: =IFERROR(D23/D19,0) -> 0 | E24: =IFERROR(E23/E19,0) -> 0 | F24: =IFERROR(F23/F19,0) -> 0 | G24: =IFERROR(G23/G19,0) -> 0 | H24: =IFERROR(H23/H19,0) -> 0 | I24: =IFERROR(I23/I19,0) -> 0
B26: Retención Móvil
C28: Sunday | D28: Monday | E28: Tuesday | F28: Wednesday | G28: Thrusday | H28: Friday | I28: Saturday
B29: HC Total Inbound | C29: =+COUNTIF(Agents!$Z$2:$Z$149,Resumen!B4) -> 0 | D29: =+C29 -> 0 | E29: =+D29 -> 0 | F29: =+E29 -> 0 | G29: =+F29 -> 0 | H29: =+G29 -> 0 | I29: =+H29 -> 0
B30: Approved OFF | C30: =+COUNTIFS(Agents!E$2:E$149,Resumen!$B30,Agents!$Z$2:$Z$149,Resumen!$B$4) -> 0 | D30: =+COUNTIFS(Agents!F$2:F$149,Resumen!$B30,Agents!$Z$2:$Z$149,Resumen!$B$4) -> 0 | E30: =+COUNTIFS(Agents!G$2:G$149,Resumen!$B30,Agents!$Z$2:$Z$149,Resumen!$B$4) -> 0 | F30: =+COUNTIFS(Agents!H$2:H$149,Resumen!$B30,Agents!$Z$2:$Z$149,Resumen!$B$4) -> 0 | G30: =+COUNTIFS(Agents!I$2:I$149,Resumen!$B30,Agents!$Z$2:$Z$149,Resumen!$B$4) -> 0 | H30: =+COUNTIFS(Agents!J$2:J$149,Resumen!$B30,Agents!$Z$2:$Z$149,Resumen!$B$4) -> 0 | I30: =+COUNTIFS(Agents!K$2:K$149,Resumen!$B30,Agents!$Z$2:$Z$149,Resumen!$B$4) -> 0
B31: LOA | C31: =+COUNTIFS(Agents!E$2:E$149,Resumen!$B31,Agents!$Z$2:$Z$149,Resumen!$B$4) -> 0 | D31: =+COUNTIFS(Agents!F$2:F$149,Resumen!$B31,Agents!$Z$2:$Z$149,Resumen!$B$4) -> 0 | E31: =+COUNTIFS(Agents!G$2:G$149,Resumen!$B31,Agents!$Z$2:$Z$149,Resumen!$B$4) -> 0 | F31: =+COUNTIFS(Agents!H$2:H$149,Resumen!$B31,Agents!$Z$2:$Z$149,Resumen!$B$4) -> 0 | G31: =+COUNTIFS(Agents!I$2:I$149,Resumen!$B31,Agents!$Z$2:$Z$149,Resumen!$B$4) -> 0 | H31: =+COUNTIFS(Agents!J$2:J$149,Resumen!$B31,Agents!$Z$2:$Z$149,Resumen!$B$4) -> 0 | I31: =+COUNTIFS(Agents!K$2:K$149,Resumen!$B31,Agents!$Z$2:$Z$149,Resumen!$B$4) -> 0
B32: OFF | C32: =+COUNTIFS(Agents!E$2:E$149,Resumen!$B32,Agents!$Z$2:$Z$149,Resumen!$B$4) -> 0 | D32: =+COUNTIFS(Agents!F$2:F$149,Resumen!$B32,Agents!$Z$2:$Z$149,Resumen!$B$4) -> 0 | E32: =+COUNTIFS(Agents!G$2:G$149,Resumen!$B32,Agents!$Z$2:$Z$149,Resumen!$B$4) -> 0 | F32: =+COUNTIFS(Agents!H$2:H$149,Resumen!$B32,Agents!$Z$2:$Z$149,Resumen!$B$4) -> 0 | G32: =+COUNTIFS(Agents!I$2:I$149,Resumen!$B32,Agents!$Z$2:$Z$149,Resumen!$B$4) -> 0 | H32: =+COUNTIFS(Agents!J$2:J$149,Resumen!$B32,Agents!$Z$2:$Z$149,Resumen!$B$4) -> 0 | I32: =+COUNTIFS(Agents!K$2:K$149,Resumen!$B32,Agents!$Z$2:$Z$149,Resumen!$B$4) -> 0
B33: Study Day | C33: =+COUNTIFS(Agents!E$2:E$149,Resumen!$B33,Agents!$Z$2:$Z$149,Resumen!$B$4) -> 0 | D33: =+COUNTIFS(Agents!F$2:F$149,Resumen!$B33,Agents!$Z$2:$Z$149,Resumen!$B$4) -> 0 | E33: =+COUNTIFS(Agents!G$2:G$149,Resumen!$B33,Agents!$Z$2:$Z$149,Resumen!$B$4) -> 0 | F33: =+COUNTIFS(Agents!H$2:H$149,Resumen!$B33,Agents!$Z$2:$Z$149,Resumen!$B$4) -> 0 | G33: =+COUNTIFS(Agents!I$2:I$149,Resumen!$B33,Agents!$Z$2:$Z$149,Resumen!$B$4) -> 0 | H33: =+COUNTIFS(Agents!J$2:J$149,Resumen!$B33,Agents!$Z$2:$Z$149,Resumen!$B$4) -> 0 | I33: =+COUNTIFS(Agents!K$2:K$149,Resumen!$B33,Agents!$Z$2:$Z$149,Resumen!$B$4) -> 0
