Workbook

Sheet Agents' Final Roster 0913-0919
A1: ACM | B1: Supervisor | C1: Last Name | D1: First Name | E1: Horario Enroque | F1: Tuesday | G1: ACDID | H1: Agent´s Payroll Number | I1: CCMSID | J1: LOB | K1: Secondary Skill | L1: Supervisor´s Payroll Numer | M1: ACM´s Payroll Number | N1: NT Loguin | O1: User #1 | P1: WAHA desde | Q1: Telephone Number | R1: DNI | S1: CUIL | T1: TPARG Hire Date | U1: Project Hire Date | V1: Production Hire Date | W1: Tenure | X1: Site | Y1: Extensión | Z1: WAHA | AA1: Horario Original
A2: Campero Juarez Maria Guadalupe | B2: Arias Juan José | C2: Bautista Boloña | D2: Luciana Florencia | E2: 15:00 - 20:00 | F2: 15:00 - 20:00 | G2: 89206 | H2: 87043 | I2: 3409624 | J2: CSV2 | K2: CSV2 | L2: 84825 | M2: 74054 | N2: bautistabolona.5 | O2: VCTLUBAU | P2: 43916 | Q2: 381-155811017 | R2: 35517416 | S2: 27355174161 | T2: 43668 | U2: 43669 | V2: 43678 | W2: 417 | X2: Campus Casino | Y2: 89953 | Z2: SI | AA2: (Hs Orig 15:00 - 20:00 OFF Dom Sab)
A3: Campero Juarez Maria Guadalupe | B3: Arias Juan José | C3: Albornoz Perez | D3: Jose Ezequiel | E3: Approved OFF | F3: Approved OFF | G3: 648060 | H3: 88037 | I3: 3553112 | J3: DVH | K3: CSV1 | L3: 84825 | M3: 74054 | N3: albornozperez.5 | O3: VCTJOALB | P3: 43943 | Q3: 03814655139 | R3: 39972625 | S3: 20-39972625-6 | T3: 43942 | U3: 43942 | V3: 43943 | W3: 148 | X3: Campus Casino | Y3: 89999 | Z3: SI | AA3: (Hs Orig 15:00 - 20:00 OFF Dom Sab)
A4: Campero Juarez Maria Guadalupe | B4: Podazza Villagra Daniel Matias | C4: Ale | D4: Rocío Agustina | E4: 15:00 - 21:00 | F4: 15:00 - 21:00 | G4: 648302 | H4: 87695 | I4: 3526421 | J4: Servicios web | K4: CSV1 | L4: 80740 | M4: 74054 | N4: ale.32 | O4: VCTROALE | P4: 43955 | Q4: 381 620 2108 | R4: 41299917 | S4: 27412999172 | T4: 43745 | U4: 43945 | V4: 43956 | W4: 342 | X4: Campus Casino | Y4: 89987 | Z4: SI | AA4: (Hs Orig 15:00 - 21:00 OFF Dom Sab)
A5: Campero Juarez Maria Guadalupe | B5: Podazza Villagra Daniel Matias | C5: Aragón | D5: Maria Celeste | E5: LOA | F5: LOA | G5: 648303 | H5: 87688 | I5: 1546296 | J5: Compras Referidas | K5: CSV1 | L5: 80740 | M5: 74054 | N5: aragon.180 | O5: VCTMAARA | P5: 43955 | Q5: 381 550 4635 | R5: 36231401 | S5: 27362314017 | T5: 43745 | U5: 43945 | V5: 43956 | W5: 342 | X5: Campus Casino | Y5: 89992 | Z5: SI | AA5: (Hs Orig 15:00 - 21:00 OFF Dom Sab)
A6: Campero Juarez Maria Guadalupe | B6: Arias Juan José | C6: Brito | D6: Jesus Exequiel | E6: 15:00 - 21:00 | F6: 15:00 - 21:00 | G6: 89069 | H6: 82613 | I6: 2313015 | J6: CSV3 | K6: CSV3 | L6: 84825 | M6: 74054 | N6: brito.272 | O6: VCTJEBRI | P6: 43917 | Q6: 03865-15419891 | R6: 37311054 | S6: 20373110540 | T6: 42688 | U6: 43369 | V6: 43403 | W6: 1385 | X6: Campus Casino | Y6: 89924 | Z6: SI | AA6: (Hs Orig 15:00 - 21:00 OFF Dom Sab)
A7: Campero Juarez Maria Guadalupe | B7: Arias Juan José | C7: Carabajal | D7: Priscila Daiana | E7: 15:00 - 21:00 | F7: 15:00 - 21:00 | G7: 89118 | H7: 86145 | I7: 2358095 | J7: CSV3 | K7: CSV3 | L7: 84825 | M7: 74054 | N7: carabajal.35 | O7: VCTPRCAR | P7: 43917 | Q7: 381-153508762 | R7: 39141166 | S7: 27391411668 | T7: 43437 | U7: 43437 | V7: 43448 | W7: 646 | X7: Campus Casino | Y7: 89925 | Z7: SI | AA7: (Hs Orig 15:00 - 21:00 OFF Dom Sab)
A8: Campero Juarez Maria Guadalupe | B8: Arias Juan José | C8: Casares | D8: Diego Jesus | E8: 15:00 - 21:00 | F8: 15:00 - 21:00 | G8: 89061 | H8: 81099 | I8: 1880623 | J8: VIP | K8: VIP/ HD | L8: 84825 | M8: 74054 | N8: casares.15 | O8: VCTDICAS | P8: 43916 | Q8: 0381-154629051 | R8: 37656704 | S8: 20376567045 | T8: 42310 | U8: 43327 | V8: 43328 | W8: 1757 | X8: Campus Casino | Y8: 89926 | Z8: SI | AA8: (Hs Orig 15:00 - 21:00 OFF Dom Sab)
A9: Campero Juarez Maria Guadalupe | B9: Podazza Villagra Daniel Matias | C9: Cejas | D9: Ignacio Martin | E9: 15:00 - 21:00 | F9: 15:00 - 21:00 | G9: 648306 | H9: 87262 | I9: 2837797 | J9: Compras Referidas | K9: CSV1 | L9: 80740 | M9: 74054 | N9: cejasguijarro.5 | O9: VCTIGCEJ | P9: 43955 | Q9: 381-154049900 | R9: 41059943 | S9: 20410599431 | T9: 43692 | U9: 43945 | V9: 43956 | W9: 394 | X9: Campus Casino | Y9: 89989 | Z9: SI | AA9: (Hs Orig 15:00 - 21:00 OFF Dom Sab)
A10: Campero Juarez Maria Guadalupe | B10: Podazza Villagra Daniel Matias | C10: Cisneros | D10: Roxana Natalia | E10: 15:00 - 21:00 | F10: 15:00 - 21:00 | G10: 89237 | H10: 87304 | I10: 3462502 | J10: Servicios web | K10: CSV1 | L10: 80740 | M10: 74054 | N10: cisneros.153 | O10: VCTROCIS | P10: 43915 | Q10: 3815811118 | R10: 30759743 | S10: 27307597433 | T10: 43703 | U10: 43703 | V10: 43713 | W10: 383 | X10: Campus Casino | Y10: 89875 | Z10: SI | AA10: (Hs Orig 15:00 - 21:00 OFF Dom Sab)
A11: Campero Juarez Maria Guadalupe | B11: Arias Juan José | C11: Corbera | D11: Elena Beatriz | E11: 15:00 - 21:00 | F11: 15:00 - 21:00 | G11: 89227 | H11: 87314 | I11: 3462518 | J11: CSV2 | K11: CSV2 | L11: 84825 | M11: 74054 | N11: corbera.8 | O11: VCTELCOR | P11: 43916 | Q11: 3816363464 | R11: 32200145 | S11: 27322001458 | T11: 43703 | U11: 43703 | V11: 43713 | W11: 383 | X11: Campus Casino | Y11: 89928 | Z11: SI | AA11: (Hs Orig 15:00 - 21:00 OFF Dom Sab)
A12: Campero Juarez Maria Guadalupe | B12: Arias Juan José | C12: Escobar | D12: Marcos Nahuel | E12: 15:00 - 21:00 | F12: 15:00 - 21:00 | G12: 89121 | H12: 86155 | I12: 2783079 | J12: CSV3 | K12: CSV3 | L12: 84825 | M12: 74054 | N12: escobar.21 | O12: VCTMAESC | P12: 43916 | Q12: 381-156538022 | R12: 38741741 | S12: 23387417419 | T12: 43437 | U12: 43437 | V12: 43448 | W12: 646 | X12: Campus Casino | Y12: 89930 | Z12: SI | AA12: (Hs Orig 15:00 - 21:00 OFF Dom Sab)
A13: Campero Juarez Maria Guadalupe | B13: Arias Juan José | C13: Juarez | D13: Carlos Luciano | E13: 15:00 - 21:00 | F13: 15:00 - 21:00 | G13: 89125 | H13: 86141 | I13: 3118306 | J13: VIP | K13: VIP | L13: 84825 | M13: 74054 | N13: Juarez.286 | O13: VCTCAJUA | P13: 43945 | Q13: 381-155399372 | R13: 40437730 | S13: 20404377303 | T13: 43437 | U13: 43437 | V13: 43448 | W13: 646 | X13: Campus Casino | Y13: 89932 | Z13: SI | AA13: (Hs Orig 15:00 - 21:00 OFF Dom Sab)
A14: Campero Juarez Maria Guadalupe | B14: Arias Juan José | C14: Muratore | D14: Daiana Gabriela | E14: 15:00 - 21:00 | F14: 15:00 - 21:00 | G14: 89053 | H14: 82401 | I14: 1063468 | J14: CSV2 | K14: CSV2 | L14: 84825 | M14: 74054 | N14: muratore.9 | O14: VCTDAMUR | P14: 43945 | Q14: 0381-153499565 | R14: 37311904 | S14: 27373119046 | T14: 42625 | U14: 43327 | V14: 43328 | W14: 1447 | X14: Campus Casino | Y14: 89933 | Z14: SI | AA14: (Hs Orig 15:00 - 21:00 OFF Dom Sab)
A15: Campero Juarez Maria Guadalupe | B15: Arias Juan José | C15: Nunez | D15: Marcelo Nahuel | E15: 15:00 - 21:00 | F15: 15:00 - 21:00 | G15: 89164 | H15: 86296 | I15: 3133293 | J15: VIP | K15: VIP | L15: 84825 | M15: 74054 | N15: nuez.128 | O15: VCTMANUN | P15: 43916 | Q15: 0381-156179830 | R15: 42221286 | S15: 20422212869 | T15: 43451 | U15: 43451 | V15: 43467 | W15: 632 | X15: Campus Casino | Y15: 89934 | Z15: SI | AA15: (Hs Orig 15:00 - 21:00 OFF Dom Sab)
A16: Campero Juarez Maria Guadalupe | B16: Arias Juan José | C16: Ortiz | D16: Silvina Gabriela | E16: 15:00 - 21:00 | F16: 15:00 - 21:00 | G16: 89027 | H16: 85614 | I16: 2873639 | J16: CSV3 | K16: CSV3 | L16: 84825 | M16: 74054 | N16: ortiz.710 | O16: VCTSIORT | P16: 43917 | Q16: 0381-154061434 | R16: 38115785 | S16: 27381157852 | T16: 43227 | U16: 43259 | V16: 43262 | W16: 852 | X16: Campus Casino | Y16: 89935 | Z16: SI | AA16: (Hs Orig 15:00 - 21:00 OFF Dom Sab)
A17: Campero Juarez Maria Guadalupe | B17: Arias Juan José | C17: Pockorny | D17: Tomás Agustín | E17: 15:00 - 21:00 | F17: 15:00 - 21:00 | G17: 89024 | H17: 85621 | I17: 2873911 | J17: HD | K17: CSV3/ HD | L17: 84825 | M17: 74054 | N17: pockorny.5 | O17: VCTTOPOC | P17: 43916 | Q17: 0381-156539796 | R17: 38185380 | S17: 20381853803 | T17: 43227 | U17: 43259 | V17: 43262 | W17: 852 | X17: Campus Casino | Y17: 89937 | Z17: SI | AA17: (Hs Orig 15:00 - 21:00 OFF Dom Sab)
A18: Campero Juarez Maria Guadalupe | B18: Podazza Villagra Daniel Matias | C18: Quiroga | D18: Marianella Stefania | E18: 15:00 - 21:00 | F18: 15:00 - 21:00 | G18: 648315 | H18: 87719 | I18: 3526375 | J18: Servicios web | K18: CSV1 | L18: 80740 | M18: 74054 | N18: quiroga.96 | O18: VCTMAQUI | P18: 43955 | Q18: 381 614 5326 | R18: 35548816 | S18: 27355488166 | T18: 43745 | U18: 43945 | V18: 43956 | W18: 342 | X18: Campus Casino | Y18: 89986 | Z18: SI | AA18: (Hs Orig 15:00 - 21:00 OFF Dom Sab)
A19: Campero Juarez Maria Guadalupe | B19: Arias Juan José | C19: Yapura | D19: Cintia Elena del Valle | E19: 09:00 - 15:00 | F19: 15:00 - 21:00 | G19: 89059 | H19: 85474 | I19: 2832262 | J19: VIP | K19: VIP/ HD | L19: 84825 | M19: 74054 | N19: yapura.5 | O19: VCTCIYAP | P19: 43910 | Q19: 0381-155060573 | R19: 40696111 | S19: 27406961112 | T19: 43193 | U19: 43327 | V19: 43328 | W19: 886 | X19: Campus Casino | Y19: 89939 | Z19: SI | AA19: (Hs Orig 15:00 - 21:00 OFF Dom Sab)
A20: Ortiz Jose María | B20: Bachur Karim | C20: Albornoz | D20: Luciana de los Angeles | E20: 15:00 - 21:00 | F20: 15:00 - 21:00 | G20: 648408 | H20: 89161 | I20: 3436665 | J20: TLMK | K20: DVH | L20: 83851 | M20: 64118 | N20: albornoz.77 | O20: VCTLUALB | R20: 31354102 | S20: 27-31354102-4 | T20: 44046 | U20: 44046 | V20: 44057 | W20: 46 | X20: Campus Casino | Z20: On Site | AA20: (Hs Orig 15:00 - 21:00 OFF Dom Sab)
A21: Ortiz Jose María | B21: Bachur Karim | C21: Avellaneda | D21: Rocío Mariel | E21: LOA | F21: LOA | G21: 648410 | H21: 89155 | I21: 3320633 | J21: TLMK | K21: DVH | L21: 83851 | M21: 64118 | N21: avellaneda.34 | O21: VCTROAVE | R21: 42371665 | S21: 27-42371665-2 | T21: 44046 | U21: 44046 | V21: 44057 | W21: 46 | X21: Campus Casino | Z21: On Site | AA21: (Hs Orig 15:00 - 21:00 OFF Dom Sab)
A22: Ortiz Jose María | B22: Bachur Karim | C22: Baez Silberstein | D22: Santiago | E22: 15:00 - 21:00 | F22: 15:00 - 21:00 | G22: 648411 | H22: 89154 | I22: 3851241 | J22: TLMK | K22: DVH | L22: 83851 | M22: 64118 | N22: baezsilberstein.5 | O22: VCTSABAE | R22: 37657560 | S22: 20-37657560-9 | T22: 44046 | U22: 44046 | V22: 44057 | W22: 46 | X22: Campus Casino | Z22: On Site | AA22: (Hs Orig 15:00 - 21:00 OFF Dom Sab)
A23: Ortiz Jose María | B23: Bachur Karim | C23: Contreras | D23: Fernando Gonzalo | E23: 15:00 - 21:00 | F23: 15:00 - 21:00 | G23: 648406 | H23: 88913 | I23: 3841619 | J23: TLMK | K23: DVH | L23: 83851 | M23: 64118 | N23: contreras.503 | O23: VCTFECON | Q23: 381-153435386 | R23: 38224052 | S23: 23-38224052-9 | T23: 44039 | U23: 44039 | V23: 44047 | W23: 52 | X23: Campus Casino | Z23: On Site | AA23: (Hs Orig 15:00 - 21:00 OFF Dom Sab)
A24: Ortiz Jose María | B24: Bachur Karim | C24: Coria | D24: Ana | E24: 15:00 - 21:00 | F24: 15:00 - 21:00 | G24: 648412 | H24: 89153 | I24: 3851249 | J24: Servicios web | K24: DVH | L24: 83851 | M24: 64118 | N24: coria.27 | O24: VCTCOANA | R24: 39142413 | S24: 27-39142413-1 | T24: 44046 | U24: 44046 | V24: 44057 | W24: 46 | X24: Campus Casino | Z24: On Site | AA24: (Hs Orig 15:00 - 21:00 OFF Dom Sab)
A25: Ortiz Jose María | B25: Bachur Karim | C25: Dilascio | D25: Miguel Angel | E25: 15:00 - 21:00 | F25: 15:00 - 21:00 | G25: 648401 | H25: 88920 | I25: 3841605 | J25: Servicios web | K25: DVH | L25: 83851 | M25: 64118 | N25: dilascio.10 | O25: VCTMIDIL | Q25: 381-155249588 | R25: 39574767 | S25: 20-39574767-4 | T25: 44039 | U25: 44039 | V25: 44047 | W25: 52 | X25: Campus Casino | Z25: On Site | AA25: (Hs Orig 15:00 - 21:00 OFF Dom Sab)
A26: Ortiz Jose María | B26: Bachur Karim | C26: Mercado | D26: Mikaela Sabrina | E26: 15:00 - 21:00 | F26: 15:00 - 21:00 | G26: 648398 | H26: 88924 | I26: 3841586 | J26: Servicios web | K26: DVH | L26: 83851 | M26: 64118 | N26: mercado.668 | O26: VCTMIMER | Q26: 381-155715427 | R26: 34327482 | S26: 27-34327482-9 | T26: 44039 | U26: 44039 | V26: 44047 | W26: 52 | X26: Campus Casino | Z26: On Site | AA26: (Hs Orig 15:00 - 21:00 OFF Dom Sab)
A27: Ortiz Jose María | B27: Bachur Karim | C27: Montaldo | D27: Sol Agustina | E27: 15:00 - 21:00 | F27: 15:00 - 21:00 | G27: 648403 | H27: 88916 | I27: 3841614 | J27: Servicios web | K27: DVH | L27: 83851 | M27: 64118 | N27: montaldo.8 | O27: VCTSOMON | Q27: 381-155455805 | R27: 41771566 | S27: 27-41771566-0 | T27: 44039 | U27: 44039 | V27: 44047 | W27: 52 | X27: Campus Casino | Z27: On Site | AA27: (Hs Orig 15:00 - 21:00 OFF Dom Sab)
A28: Ortiz Jose María | B28: Bachur Karim | C28: Navarro | D28: Luciana Antonella | E28: 15:00 - 21:00 | F28: 15:00 - 21:00 | G28: 648407 | H28: 88917 | I28: 3841622 | J28: Servicios web | K28: DVH | L28: 83851 | M28: 64118 | N28: navarro.873 | O28: VCTANNAV | Q28: 381-155013812 | R28: 38244120 | S28: 27-38244120-1 | T28: 44039 | U28: 44039 | V28: 44047 | W28: 52 | X28: Campus Casino | Z28: On Site | AA28: (Hs Orig 15:00 - 21:00 OFF Dom Sab)
A29: Ortiz Jose María | B29: Bachur Karim | C29: Pascual | D29: Silvio Daniel | E29: 15:00 - 21:00 | F29: 15:00 - 21:00 | G29: 648405 | H29: 88919 | I29: 3841618 | J29: Servicios web | K29: DVH | L29: 83851 | M29: 64118 | N29: pascual.465 | O29: VCTSIPAS | Q29: 381-153362589 | R29: 36439725 | S29: 23-36439725-9 | T29: 44039 | U29: 44039 | V29: 44047 | W29: 52 | X29: Campus Casino | Z29: On Site | AA29: (Hs Orig 15:00 - 21:00 OFF Dom Sab)
A30: Ortiz Jose María | B30: Bachur Karim | C30: Rodríguez | D30: Brenda Agostina | E30: 15:00 - 21:00 | F30: 15:00 - 21:00 | G30: 648402 | H30: 88922 | I30: 3841611 | J30: DVH | K30: DVH | L30: 83851 | M30: 64118 | N30: rodriguez.4165 | O30: VCTBRROD | Q30: 381-156070741 | R30: 39730809 | S30: 27-39730809-5 | T30: 44039 | U30: 44039 | V30: 44047 | W30: 52 | X30: Campus Casino | Z30: On Site | AA30: (Hs Orig 15:00 - 21:00 OFF Dom Sab)
A31: Ortiz Jose María | B31: Bachur Karim | C31: Terriaca Lemme | D31: Flavia Solaina | E31: 15:00 - 21:00 | F31: 15:00 - 21:00 | G31: 648399 | H31: 88914 | I31: 3841590 | J31: DVH | K31: DVH | L31: 83851 | M31: 64118 | N31: terriacalemme.5 | O31: VCTFLTER | Q31: 381-153016768 | R31: 35195568 | S31: 27-35195568-1 | T31: 44039 | U31: 44039 | V31: 44047 | W31: 52 | X31: Campus Casino | Z31: On Site | AA31: (Hs Orig 15:00 - 21:00 OFF Dom Sab)
A32: Ortiz Jose María | B32: Bachur Karim | C32: Ucciardello | D32: Luciana Daniza | E32: 15:00 - 21:00 | F32: 15:00 - 21:00 | G32: 648400 | H32: 88921 | I32: 3557330 | J32: DVH | K32: DVH | L32: 83851 | M32: 64118 | N32: ucciardello.5 | O32: VCTLUUCC | Q32: 381-153396910 | R32: 42548543 | S32: 27-42548543-7 | T32: 44039 | U32: 44039 | V32: 44047 | W32: 52 | X32: Campus Casino | Z32: On Site | AA32: (Hs Orig 15:00 - 21:00 OFF Dom Sab)
A33: Ortiz Jose María | B33: Bachur Karim | C33: Yanelli | D33: Aníbal Hector Francisco | E33: 15:00 - 21:00 | F33: 15:00 - 21:00 | G33: 648404 | H33: 88915 | I33: 3841616 | J33: DVH | K33: DVH | L33: 83851 | M33: 64118 | N33: yanelli.5 | O33: VCTANYAN | Q33: 381-15 6576805 | R33: 42371182 | S33: 20-42371182-6 | T33: 44039 | U33: 44039 | V33: 44047 | W33: 52 | X33: Campus Casino | Z33: On Site | AA33: (Hs Orig 15:00 - 21:00 OFF Dom Sab)
A34: Campero Juarez Maria Guadalupe | B34: Corbera Susana Sofía | C34: Alonso | D34: Facundo ismael | E34: 15:00 - 21:00 | F34: 15:00 - 21:00 | G34: 89313 | H34: 88174 | I34: 3624184 | J34: CSV2 | K34: CSV2 | L34: 81043 | M34: 74054 | N34: alonso.155 | O34: VCTFAALO | P34: 43917 | R34: 42007693 | S34: 20420076933 | T34: 43808 | U34: 43808 | V34: 43831 | W34: 280 | X34: Campus Casino | Y34: 89871 | Z34: SI | AA34: (Hs Orig 15:00 - 21:00 OFF Dom Sab)
A35: Campero Juarez Maria Guadalupe | B35: Corbera Susana Sofía | C35: Alvarez Maziad | D35: Monica Carolina | E35: 15:00 - 21:00 | F35: 15:00 - 21:00 | G35: 89057 | H35: 83603 | I35: 2523112 | J35: CSV2 | K35: CSV2 | L35: 81043 | M35: 74054 | N35: alvarezmaziad.5 | O35: VCTMOALV | P35: 43917 | Q35: 0381-156802261 | R35: 39145406 | S35: 27391454065 | T35: 42891 | U35: 43327 | V35: 43328 | W35: 1184 | X35: Campus Casino | Y35: 89940 | Z35: SI | AA35: (Hs Orig 15:00 - 21:00 OFF Dom Sab)
A36: Campero Juarez Maria Guadalupe | B36: Corbera Susana Sofía | C36: Azubel | D36: Solange | E36: 15:00 - 21:00 | F36: 15:00 - 21:00 | G36: 89225 | H36: 87316 | I36: 1100247 | J36: CSV3 | K36: CSV3 | L36: 81043 | M36: 74054 | N36: azubel.7 | O36: VCTSOAZU | P36: 43916 | Q36: 3814637258 | R36: 35921500 | S36: 27359215008 | T36: 43703 | U36: 43703 | V36: 43713 | W36: 383 | X36: Campus Casino | Y36: 89941 | Z36: SI | AA36: (Hs Orig 15:00 - 21:00 OFF Dom Sab)
A37: Campero Juarez Maria Guadalupe | B37: Corbera Susana Sofía | C37: Cantos | D37: Horacio Nicolas | E37: 15:00 - 21:00 | F37: 15:00 - 21:00 | G37: 89236 | H37: 87308 | I37: 3462509 | J37: CSV3 | K37: CSV3 | L37: 81043 | M37: 74054 | N37: cantos.58 | O37: VCTHOCAN | P37: 43915 | Q37: 3814742874 | R37: 41650790 | S37: 20416507903 | T37: 43703 | U37: 43703 | V37: 43713 | W37: 383 | X37: Campus Casino | Y37: 89944 | Z37: SI | AA37: (Hs Orig 15:00 - 21:00 OFF Dom Sab)
A38: Campero Juarez Maria Guadalupe | B38: Corbera Susana Sofía | C38: Castillo | D38: Angel Alberto | E38: 15:00 - 21:00 | F38: 15:00 - 21:00 | G38: 89104 | H38: 85278 | I38: 2803851 | J38: CSV3 | K38: CSV3 | L38: 81043 | M38: 74054 | N38: castillo.1268 | O38: VCTANCAS | P38: 43910 | Q38: 3816509596 | R38: 37457052 | S38: 20374570529 | T38: 43164 | U38: 43409 | V38: 43423 | W38: 914 | X38: Campus Casino | Y38: 89945 | Z38: SI | AA38: (Hs Orig 15:00 - 21:00 OFF Dom Sab)
A39: Campero Juarez Maria Guadalupe | B39: Corbera Susana Sofía | C39: Chavarria Bevacqua | D39: Silvana Carolina | E39: 15:00 - 20:00 | F39: 15:00 - 20:00 | G39: 89207 | H39: 87045 | I39: 3409666 | J39: CSV2 | K39: CSV2 | L39: 81043 | M39: 74054 | N39: chavarriabevacqua.5 | O39: VCTSICHA | P39: 43916 | Q39: 381-156956998 | R39: 35192091 | S39: 27-35192091-8 | T39: 43668 | U39: 43669 | V39: 43678 | W39: 417 | X39: Campus Casino | Y39: 89887 | Z39: SI | AA39: (Hs Orig 15:00 - 20:00 OFF Dom Sab)
A40: Campero Juarez Maria Guadalupe | B40: Corbera Susana Sofía | C40: Del Pino | D40: Agustin Alejandro | E40: Approved OFF | F40: Approved OFF | G40: 89211 | H40: 87057 | I40: 3409641 | J40: DVH | K40: CSV1 | L40: 81043 | M40: 74054 | N40: delpino.12 | O40: VCTAGDEL | P40: 43945 | Q40: 381-155438690 | R40: 41495060 | S40: 20414950605 | T40: 43668 | U40: 43669 | V40: 43678 | W40: 417 | X40: Campus Casino | Y40: 89876 | Z40: SI | AA40: (Hs Orig 16:00 - 21:00 OFF Dom Sab)
...

Sheet Sups' Final Roster 0913-0919
A1: ACM | B1: Supervisor | C1: Sunday | D1: Monday | E1: Tuesday | F1: Wednesday | G1: Thrusday | H1: Friday | I1: Saturday | J1: Legajo | K1: CCMSID
A2: Campero Juarez Maria Guadalupe | B2: Arias Juan José | C2: OFF | D2: 12:00 - 21:00 | E2: 12:00 - 21:00 | F2: 12:00 - 21:00 | G2: 12:00 - 21:00 | H2: 12:00 - 21:00 | I2: OFF | J2: 84825 | K2: 2770365
A3: Campero Juarez Maria Guadalupe | B3: Corbera Susana Sofía | C3: OFF | D3: 12:00 - 21:00 | E3: 12:00 - 21:00 | F3: 12:00 - 21:00 | G3: 12:00 - 21:00 | H3: 12:00 - 21:00 | I3: OFF | J3: 81043 | K3: 1880608
A4: Campero Juarez Maria Guadalupe | B4: Podazza Villagra Daniel Matias | C4: OFF | D4: 12:00 - 21:00 | E4: 12:00 - 21:00 | F4: 12:00 - 21:00 | G4: 12:00 - 21:00 | H4: 12:00 - 21:00 | I4: OFF | J4: 80740 | K4: 1793255
A5: Campero Juarez Maria Guadalupe | B5: Gregoratti Juan Carlos | C5: OFF | D5: 12:00 - 21:00 | E5: 12:00 - 21:00 | F5: 12:00 - 21:00 | G5: 12:00 - 21:00 | H5: 12:00 - 21:00 | I5: OFF | J5: 79688 | K5: 1453697
A6: Pérez Zitzke Agustina | B6: Vazquez Valladares Eduardo Alejandro | C6: OFF | D6: 12:00 - 21:00 | E6: 12:00 - 21:00 | F6: 12:00 - 21:00 | G6: 12:00 - 21:00 | H6: 12:00 - 21:00 | I6: OFF | J6: 77681 | K6: 1077981
A7: Pérez Zitzke Agustina | B7: Ramallo Jose Emanuel | C7: OFF | D7: 12:00 - 21:00 | E7: 12:00 - 21:00 | F7: 12:00 - 21:00 | G7: 12:00 - 21:00 | H7: 12:00 - 21:00 | I7: OFF | J7: 79479 | K7: 1407265
A8: Campero Juarez Maria Guadalupe | B8: Criado Esteban | C8: OFF | D8: 12:00 - 21:00 | E8: 12:00 - 21:00 | F8: 12:00 - 21:00 | G8: 12:00 - 21:00 | H8: 12:00 - 21:00 | I8: OFF | J8: 85154 | K8: 1815266
A9: Ortiz Jose María | B9: Diaz Jesica Luciana | C9: OFF | D9: 07:30 - 16:30 | E9: 07:30 - 16:30 | F9: 07:30 - 16:30 | G9: 07:30 - 16:30 | H9: 07:30 - 16:30 | I9: OFF | J9: 66977 | K9: 500642
A10: Pérez Zitzke Agustina | B10: Villa Aleman Alejandro Roberto | C10: OFF | D10: 08:00 - 17:00 | E10: 08:00 - 17:00 | F10: 08:00 - 17:00 | G10: 08:00 - 17:00 | H10: 08:00 - 17:00 | I10: OFF | J10: 81755 | K10: 2052783
A11: Ortiz Jose María | B11: Brandan Ernesto Alejandro | C11: OFF | D11: 08:00 - 17:00 | E11: 08:00 - 17:00 | F11: 08:00 - 17:00 | G11: 08:00 - 17:00 | H11: 08:00 - 17:00 | I11: OFF | J11: 74323 | K11: 595902
A12: Ortiz Jose María | B12: Britos Fernando José | C12: OFF | D12: 08:00 - 17:00 | E12: 08:00 - 17:00 | F12: 08:00 - 17:00 | G12: 08:00 - 17:00 | H12: 08:00 - 17:00 | I12: OFF | J12: 70271 | K12: 490014
A13: Ortiz Jose María | B13: Esquivel Pavan Pamela Sol | C13: OFF | D13: 08:00 - 17:00 | E13: 08:00 - 17:00 | F13: 08:00 - 17:00 | G13: 08:00 - 17:00 | H13: 08:00 - 17:00 | I13: OFF | J13: 78667 | K13: 1244026
... A20: Ortiz Jose María | B20: Silva Gabriel Alberto | C20: OFF | D20: 08:00 - 17:00 | E20: 08:00 - 17:00 | F20: 08:00 - 17:00 | G20: 08:00 - 17:00 | H20: 08:00 - 17:00 | I20: OFF | J20: 84144 | K20: 2714348

Sheet ACMs' Final Roster 0913-0919
A1: CCM | B1: ACM | C1: Sunday | D1: Monday | E1: Tuesday | F1: Wednesday | G1: Thrusday | H1: Friday | I1: Saturday | J1: Legajo | K1: CCMSID
A2: Décima Romina Soledad | B2: Ortiz Jose María | C2: OFF | D2: 09:00 - 18:00 | E2: 09:00 - 18:00 | F2: 09:00 - 18:00 | G2: 09:00 - 18:00 | H2: 09:00 - 18:00 | I2: OFF | J2: 64118 | K2: 433569
A3: Décima Romina Soledad | B3: Campero Juarez Maria Guadalupe | C3: OFF | D3: 11:00 - 20:00 | E3: 11:00 - 20:00 | F3: 11:00 - 20:00 | G3: 11:00 - 20:00 | H3: 11:00 - 20:00 | I3: OFF | J3: 74054 | K3: 590259
A4: Décima Romina Soledad | B4: Pérez Zitzke Agustina | C4: OFF | D4: 09:00 - 18:00 | E4: 09:00 - 18:00 | F4: 09:00 - 18:00 | G4: 09:00 - 18:00 | H4: 09:00 - 18:00 | I4: OFF | J4: 59438 | K4: 433173

Sheet Ratios
A1: RATIO Prisma
A3: ACM | B3: Supervisor | C3: Supervisores | D3: Share | H3: ACM | I3: Supervisor | J3: Agentes | K3: Share
A4: Ortiz Jose María | B4: Diaz Jesica Luciana | C4: 20 | D4: 0.06116208 | H4: Ortiz Jose María | I4: Brandan Ernesto Alejandro | J4: 21 | K4: 0.10144928
B5: Brandan Ernesto Alejandro | C5: 21 | D5: 0.064220183 | I5: Esquivel Pavan Pamela Sol | J5: 21 | K5: 0.10144928
B6: Esquivel Pavan Pamela Sol | C6: 21 | D6: 0.064220183 | I6: Diaz Jesica Luciana | J6: 20 | K6: 0.096618357
B7: Gerez Andrea Soledad | C7: 19 | D7: 0.058103976 | I7: Gerez Andrea Soledad | J7: 19 | K7: 0.09178744
B8: Britos Fernando José | C8: 16 | D8: 0.048929664 | I8: Britos Fernando José | J8: 16 | K8: 0.077294686
B9: Silva Gabriel Alberto | C9: 9 | D9: 0.027522936 | H9: Ortiz Jose María Total | J9: 97 | K9: 0.46859903
A10: Ortiz Jose María Total | C10: 106 | D10: 0.32415902 | H10: Campero Juarez Maria Guadalupe | I10: Podazza Villagra Daniel Matias | J10: 19 | K10: 0.09178744
A11: Campero Juarez Maria Guadalupe | B11: Arias Juan José | C11: 18 | D11: 0.055045872 | I11: Corbera Susana Sofía | J11: 19 | K11: 0.09178744
B12: Podazza Villagra Daniel Matias | C12: 19 | D12: 0.058103976 | I12: Arias Juan José | J12: 18 | K12: 0.086956522
B13: Gregoratti Juan Carlos | C13: 17 | D13: 0.051987768 | I13: Gregoratti Juan Carlos | J13: 17 | K13: 0.082125604
B14: Corbera Susana Sofía | C14: 19 | D14: 0.058103976 | H14: Campero Juarez Maria Guadalupe Total | J14: 73 | K14: 0.352657
B15: Criado Esteban | C15: 20 | D15: 0.06116208 | H15: Perez Zitzke Agustina | I15: Villa Aleman Alejandro Roberto | J15: 21 | K15: 0.10144928
B16: Bachur Karim | C16: 14 | D16: 0.042813456 | I16: Vazquez Valladares Eduardo Alejandro | J16: 16 | K16: 0.077294686
B17: Mendoza Norma Mercedes | C17: 13 | D17: 0.039755352 | H17: Perez Zitzke Agustina Total | J17: 37 | K17: 0.17874396
A18: Campero Juarez Maria Guadalupe Total | C18: 120 | D18: 0.36697248 | H18: Grand Total | J18: 207 | K18: 1
A19: Perez Zitzke Agustina | B19: Vazquez Valladares Eduardo Alejandro | C19: 16 | D19: 0.048929664
B20: Villa Aleman Alejandro Roberto | C20: 21 | D20: 0.064220183
B21: Grimaldi Agustina Sofía | C21: 17 | D21: 0.051987768
B22: Ramallo Jose Emanuel | C22: 19 | D22: 0.058103976
B23: Palomino Juan Pablo | C23: 19 | D23: 0.058103976
B24: Albornoz Miguel | C24: 9 | D24: 0.027522936
A25: Perez Zitzke Agustina Total | C25: 101 | D25: 0.3088685
A26: Grand Total | C26: 327 | D26: 1

Sheet Agents
A1: ACM | B1: Supervisor | C1: Last Name | D1: First Name | E1: Sunday | F1: Monday | G1: Tuesday | H1: Wednesday | I1: Thrusday | J1: Friday | K1: Saturday | L1: Attriton Date | M1: Comments | N1: Type | O1: Sun Hrs. | P1: Mon Hrs. | Q1: Tue Hrs. | R1: Wed Hrs. | S1: Thu Hrs. | T1: Fri Hrs. | U1: Sat Hrs. | V1: Scheduled Hrs. | W1: ACDID | X1: Agent´s Payroll Number | Y1: CCMSID | Z1: LOB | AA1: Secondary Skill | AB1: Supervisor´s Payroll Numer | AC1: ACM´s Payroll Number | AD1: NT Loguin | AE1: User #1 | AF1: User #2 | AG1: Telephone Number | AH1: DNI | AI1: CUIL | AJ1: TPARG Hire Date | AK1: Project Hire Date | AL1: Production Hire Date | AM1: Tenure | AN1: Site | AO1: Set Skill Programado | AP1: LOA
A2: ='Agents'' Final Roster 0913-0919'!A2 -> Campero Juarez Maria Guadalupe | B2: ='Agents'' Final Roster 0913-0919'!B2 -> Arias Juan José | C2: ='Agents'' Final Roster 0913-0919'!C2 -> Bautista Boloña | D2: ='Agents'' Final Roster 0913-0919'!D2 -> Luciana Florencia | Z2: ='Agents'' Final Roster 0913-0919'!J2 -> CSV2
A3: ='Agents'' Final Roster 0913-0919'!A3 -> Campero Juarez Maria Guadalupe | B3: ='Agents'' Final Roster 0913-0919'!B3 -> Arias Juan José | C3: ='Agents'' Final Roster 0913-0919'!C3 -> Albornoz Perez | D3: ='Agents'' Final Roster 0913-0919'!D3 -> Jose Ezequiel | Z3: ='Agents'' Final Roster 0913-0919'!J3 -> DVH
A4: ='Agents'' Final Roster 0913-0919'!A4 -> Campero Juarez Maria Guadalupe | B4: ='Agents'' Final Roster 0913-0919'!B4 -> Podazza Villagra Daniel Matias | C4: ='Agents'' Final Roster 0913-0919'!C4 -> Ale | D4: ='Agents'' Final Roster 0913-0919'!D4 -> Rocío Agustina | Z4: ='Agents'' Final Roster 0913-0919'!J4 -> Servicios web
A5: ='Agents'' Final Roster 0913-0919'!A5 -> Campero Juarez Maria Guadalupe | B5: ='Agents'' Final Roster 0913-0919'!B5 -> Podazza Villagra Daniel Matias | C5: ='Agents'' Final Roster 0913-0919'!C5 -> Aragón | D5: ='Agents'' Final Roster 0913-0919'!D5 -> Maria Celeste | Z5: ='Agents'' Final Roster 0913-0919'!J5 -> Compras Referidas
A6: ='Agents'' Final Roster 0913-0919'!A6 -> Campero Juarez Maria Guadalupe | B6: ='Agents'' Final Roster 0913-0919'!B6 -> Arias Juan José | C6: ='Agents'' Final Roster 0913-0919'!C6 -> Brito | D6: ='Agents'' Final Roster 0913-0919'!D6 -> Jesus Exequiel | Z6: ='Agents'' Final Roster 0913-0919'!J6 -> CSV3
A7: ='Agents'' Final Roster 0913-0919'!A7 -> Campero Juarez Maria Guadalupe | B7: ='Agents'' Final Roster 0913-0919'!B7 -> Arias Juan José | C7: ='Agents'' Final Roster 0913-0919'!C7 -> Carabajal | D7: ='Agents'' Final Roster 0913-0919'!D7 -> Priscila Daiana | Z7: ='Agents'' Final Roster 0913-0919'!J7 -> CSV3
A8: ='Agents'' Final Roster 0913-0919'!A8 -> Campero Juarez Maria Guadalupe | B8: ='Agents'' Final Roster 0913-0919'!B8 -> Arias Juan José | C8: ='Agents'' Final Roster 0913-0919'!C8 -> Casares | D8: ='Agents'' Final Roster 0913-0919'!D8 -> Diego Jesus | Z8: ='Agents'' Final Roster 0913-0919'!J8 -> VIP
A9: ='Agents'' Final Roster 0913-0919'!A9 -> Campero Juarez Maria Guadalupe | B9: ='Agents'' Final Roster 0913-0919'!B9 -> Podazza Villagra Daniel Matias | C9: ='Agents'' Final Roster 0913-0919'!C9 -> Cejas | D9: ='Agents'' Final Roster 0913-0919'!D9 -> Ignacio Martin | Z9: ='Agents'' Final Roster 0913-0919'!J9 -> Compras Referidas
A10: ='Agents'' Final Roster 0913-0919'!A10 -> Campero Juarez Maria Guadalupe | B10: ='Agents'' Final Roster 0913-0919'!B10 -> Podazza Villagra Daniel Matias | C10: ='Agents'' Final Roster 0913-0919'!C10 -> Cisneros | D10: ='Agents'' Final Roster 0913-0919'!D10 -> Roxana Natalia | Z10: ='Agents'' Final Roster 0913-0919'!J10 -> Servicios web
A11: ='Agents'' Final Roster 0913-0919'!A11 -> Campero Juarez Maria Guadalupe | B11: ='Agents'' Final Roster 0913-0919'!B11 -> Arias Juan José | C11: ='Agents'' Final Roster 0913-0919'!C11 -> Corbera | D11: ='Agents'' Final Roster 0913-0919'!D11 -> Elena Beatriz | Z11: ='Agents'' Final Roster 0913-0919'!J11 -> CSV2
A12: ='Agents'' Final Roster 0913-0919'!A12 -> Campero Juarez Maria Guadalupe | B12: ='Agents'' Final Roster 0913-0919'!B12 -> Arias Juan José | C12: ='Agents'' Final Roster 0913-0919'!C12 -> Escobar | D12: ='Agents'' Final Roster 0913-0919'!D12 -> Marcos Nahuel | Z12: ='Agents'' Final Roster 0913-0919'!J12 -> CSV3
A13: ='Agents'' Final Roster 0913-0919'!A13 -> Campero Juarez Maria Guadalupe | B13: ='Agents'' Final Roster 0913-0919'!B13 -> Arias Juan José | C13: ='Agents'' Final Roster 0913-0919'!C13 -> Juarez | D13: ='Agents'' Final Roster 0913-0919'!D13 -> Carlos Luciano | Z13: ='Agents'' Final Roster 0913-0919'!J13 -> VIP
... A184: ='Agents'' Final Roster 0913-0919'!A184 -> Ortiz Jose María | B184: ='Agents'' Final Roster 0913-0919'!B184 -> Esquivel Pavan Pamela Sol | C184: ='Agents'' Final Roster 0913-0919'!C184 -> Correa | D184: ='Agents'' Final Roster 0913-0919'!D184 -> David Maximiliano | Z184: ='Agents'' Final Roster 0913-0919'!J184 -> DVH
A185: ='Agents'' Final Roster 0913-0919'!#REF! -> #REF! | B185: ='Agents'' Final Roster 0913-0919'!#REF! -> #REF! | C185: ='Agents'' Final Roster 0913-0919'!#REF! -> #REF! | D185: ='Agents'' Final Roster 0913-0919'!#REF! -> #REF! | Z185: ='Agents'' Final Roster 0913-0919'!#REF! -> #REF!
A186: ='Agents'' Final Roster 0913-0919'!#REF! -> #REF! | B186: ='Agents'' Final Roster 0913-0919'!#REF! -> #REF! | C186: ='Agents'' Final Roster 0913-0919'!#REF! -> #REF! | D186: ='Agents'' Final Roster 0913-0919'!#REF! -> #REF! | Z186: ='Agents'' Final Roster 0913-0919'!#REF! -> #REF!
A187: ='Agents'' Final Roster 0913-0919'!#REF! -> #REF! | B187: ='Agents'' Final Roster 0913-0919'!#REF! -> #REF! | C187: ='Agents'' Final Roster 0913-0919'!#REF! -> #REF! | D187: ='Agents'' Final Roster 0913-0919'!#REF! -> #REF! | Z187: ='Agents'' Final Roster 0913-0919'!#REF! -> #REF!
A188: ='Agents'' Final Roster 0913-0919'!#REF! -> #REF! | B188: ='Agents'' Final Roster 0913-0919'!#REF! -> #REF! | C188: ='Agents'' Final Roster 0913-0919'!#REF! -> #REF! | D188: ='Agents'' Final Roster 0913-0919'!#REF! -> #REF! | Z188: ='Agents'' Final Roster 0913-0919'!#REF! -> #REF!
A189: ='Agents'' Final Roster 0913-0919'!#REF! -> #REF! | B189: ='Agents'' Final Roster 0913-0919'!#REF! -> #REF! | C189: ='Agents'' Final Roster 0913-0919'!#REF! -> #REF! | D189: ='Agents'' Final Roster 0913-0919'!#REF! -> #REF! | Z189: ='Agents'' Final Roster 0913-0919'!#REF! -> #REF!
A190: ='Agents'' Final Roster 0913-0919'!#REF! -> #REF! | B190: ='Agents'' Final Roster 0913-0919'!#REF! -> #REF! | C190: ='Agents'' Final Roster 0913-0919'!#REF! -> #REF! | D190: ='Agents'' Final Roster 0913-0919'!#REF! -> #REF! | Z190: ='Agents'' Final Roster 0913-0919'!#REF! -> #REF!
A191: ='Agents'' Final Roster 0913-0919'!#REF! -> #REF! | B191: ='Agents'' Final Roster 0913-0919'!#REF! -> #REF! | C191: ='Agents'' Final Roster 0913-0919'!#REF! -> #REF! | D191: ='Agents'' Final Roster 0913-0919'!#REF! -> #REF! | Z191: ='Agents'' Final Roster 0913-0919'!#REF! -> #REF!
A192: ='Agents'' Final Roster 0913-0919'!#REF! -> #REF! | B192: ='Agents'' Final Roster 0913-0919'!#REF! -> #REF! | C192: ='Agents'' Final Roster 0913-0919'!#REF! -> #REF! | D192: ='Agents'' Final Roster 0913-0919'!#REF! -> #REF! | Z192: ='Agents'' Final Roster 0913-0919'!#REF! -> #REF!
A193: ='Agents'' Final Roster 0913-0919'!#REF! -> #REF! | B193: ='Agents'' Final Roster 0913-0919'!#REF! -> #REF! | C193: ='Agents'' Final Roster 0913-0919'!#REF! -> #REF! | D193: ='Agents'' Final Roster 0913-0919'!#REF! -> #REF! | Z193: ='Agents'' Final Roster 0913-0919'!#REF! -> #REF!
A194: ='Agents'' Final Roster 0913-0919'!#REF! -> #REF! | B194: ='Agents'' Final Roster 0913-0919'!#REF! -> #REF! | C194: ='Agents'' Final Roster 0913-0919'!#REF! -> #REF! | D194: ='Agents'' Final Roster 0913-0919'!#REF! -> #REF! | Z194: ='Agents'' Final Roster 0913-0919'!#REF! -> #REF!
A195: ='Agents'' Final Roster 0913-0919'!#REF! -> #REF! | B195: ='Agents'' Final Roster 0913-0919'!#REF! -> #REF! | C195: ='Agents'' Final Roster 0913-0919'!#REF! -> #REF! | D195: ='Agents'' Final Roster 0913-0919'!#REF! -> #REF! | Z195: ='Agents'' Final Roster 0913-0919'!#REF! -> #REF!
A196: ='Agents'' Final Roster 0913-0919'!#REF! -> #REF! | B196: ='Agents'' Final Roster 0913-0919'!#REF! -> #REF! | C196: ='Agents'' Final Roster 0913-0919'!#REF! -> #REF! | D196: ='Agents'' Final Roster 0913-0919'!#REF! -> #REF! | Z196: ='Agents'' Final Roster 0913-0919'!#REF! -> #REF!
... A239: ='Agents'' Final Roster 0913-0919'!#REF! -> #REF! | B239: ='Agents'' Final Roster 0913-0919'!#REF! -> #REF! | C239: ='Agents'' Final Roster 0913-0919'!#REF! -> #REF! | D239: ='Agents'' Final Roster 0913-0919'!#REF! -> #REF! | Z239: ='Agents'' Final Roster 0913-0919'!#REF! -> #REF!
A240: ='Agents'' Final Roster 0913-0919'!A185 -> Ortiz Jose María | B240: ='Agents'' Final Roster 0913-0919'!B185 -> Esquivel Pavan Pamela Sol | C240: ='Agents'' Final Roster 0913-0919'!C185 -> Guevara | D240: ='Agents'' Final Roster 0913-0919'!D185 -> Carlos Augusto | Z240: ='Agents'' Final Roster 0913-0919'!J185 -> CSV2
A241: ='Agents'' Final Roster 0913-0919'!A186 -> Ortiz Jose María | B241: ='Agents'' Final Roster 0913-0919'!B186 -> Esquivel Pavan Pamela Sol | C241: ='Agents'' Final Roster 0913-0919'!C186 -> Jerez | D241: ='Agents'' Final Roster 0913-0919'!D186 -> Rodrigo Facundo | Z241: ='Agents'' Final Roster 0913-0919'!J186 -> CSV1
A242: ='Agents'' Final Roster 0913-0919'!A187 -> Ortiz Jose María | B242: ='Agents'' Final Roster 0913-0919'!B187 -> Esquivel Pavan Pamela Sol | C242: ='Agents'' Final Roster 0913-0919'!C187 -> Lazarte | D242: ='Agents'' Final Roster 0913-0919'!D187 -> Carlos Enrique | Z242: ='Agents'' Final Roster 0913-0919'!J187 -> DVH
A243: ='Agents'' Final Roster 0913-0919'!A188 -> Ortiz Jose María | B243: ='Agents'' Final Roster 0913-0919'!B188 -> Esquivel Pavan Pamela Sol | C243: ='Agents'' Final Roster 0913-0919'!C188 -> Lopez | D243: ='Agents'' Final Roster 0913-0919'!D188 -> Franco Daniel | Z243: ='Agents'' Final Roster 0913-0919'!J188 -> Servicios web
A244: ='Agents'' Final Roster 0913-0919'!A189 -> Ortiz Jose María | B244: ='Agents'' Final Roster 0913-0919'!B189 -> Esquivel Pavan Pamela Sol | C244: ='Agents'' Final Roster 0913-0919'!C189 -> Mendez | D244: ='Agents'' Final Roster 0913-0919'!D189 -> Maria Laura | Z244: ='Agents'' Final Roster 0913-0919'!J189 -> CSV1
A245: ='Agents'' Final Roster 0913-0919'!A190 -> Ortiz Jose María | B245: ='Agents'' Final Roster 0913-0919'!B190 -> Esquivel Pavan Pamela Sol | C245: ='Agents'' Final Roster 0913-0919'!C190 -> Moreno | D245: ='Agents'' Final Roster 0913-0919'!D190 -> Fatima Rocio Belen | Z245: ='Agents'' Final Roster 0913-0919'!J190 -> CSV1
A246: ='Agents'' Final Roster 0913-0919'!A191 -> Ortiz Jose María | B246: ='Agents'' Final Roster 0913-0919'!B191 -> Esquivel Pavan Pamela Sol | C246: ='Agents'' Final Roster 0913-0919'!C191 -> Navarro | D246: ='Agents'' Final Roster 0913-0919'!D191 -> Luciano Gustavo | Z246: ='Agents'' Final Roster 0913-0919'!J191 -> CSV2
A247: ='Agents'' Final Roster 0913-0919'!A192 -> Ortiz Jose María | B247: ='Agents'' Final Roster 0913-0919'!B192 -> Esquivel Pavan Pamela Sol | C247: ='Agents'' Final Roster 0913-0919'!C192 -> Perez | D247: ='Agents'' Final Roster 0913-0919'!D192 -> Maria Jose | Z247: ='Agents'' Final Roster 0913-0919'!J192 -> CSV1
A248: ='Agents'' Final Roster 0913-0919'!A193 -> Ortiz Jose María | B248: ='Agents'' Final Roster 0913-0919'!B193 -> Esquivel Pavan Pamela Sol | C248: ='Agents'' Final Roster 0913-0919'!C193 -> Reinoso Cisnero | D248: ='Agents'' Final Roster 0913-0919'!D193 -> Gaspar | Z248: ='Agents'' Final Roster 0913-0919'!J193 -> Servicios web
A249: ='Agents'' Final Roster 0913-0919'!A194 -> Ortiz Jose María | B249: ='Agents'' Final Roster 0913-0919'!B194 -> Esquivel Pavan Pamela Sol | C249: ='Agents'' Final Roster 0913-0919'!C194 -> Rodriguez | D249: ='Agents'' Final Roster 0913-0919'!D194 -> Alejandra Isabel | Z249: ='Agents'' Final Roster 0913-0919'!J194 -> Compras Referidas
A250: ='Agents'' Final Roster 0913-0919'!A195 -> Ortiz Jose María | B250: ='Agents'' Final Roster 0913-0919'!B195 -> Esquivel Pavan Pamela Sol | C250: ='Agents'' Final Roster 0913-0919'!C195 -> Rossi | D250: ='Agents'' Final Roster 0913-0919'!D195 -> Griselda Analia | Z250: ='Agents'' Final Roster 0913-0919'!J195 -> CSV2
A251: ='Agents'' Final Roster 0913-0919'!A196 -> Ortiz Jose María | B251: ='Agents'' Final Roster 0913-0919'!B196 -> Esquivel Pavan Pamela Sol | C251: ='Agents'' Final Roster 0913-0919'!C196 -> Rotondo | D251: ='Agents'' Final Roster 0913-0919'!D196 -> Eliana Romina | Z251: ='Agents'' Final Roster 0913-0919'!J196 -> CSV1
... A306: ='Agents'' Final Roster 0913-0919'!A251 -> Perez Zitzke Agustina | B306: ='Agents'' Final Roster 0913-0919'!B251 -> Grimaldi Agustina Sofía | C306: ='Agents'' Final Roster 0913-0919'!C251 -> Uncos | D306: ='Agents'' Final Roster 0913-0919'!D251 -> Cristian Carlos | Z306: ='Agents'' Final Roster 0913-0919'!J251 -> Compras Referidas
...

Sheet Sups
A1: ACM | B1: Supervisor | C1: Sunday | D1: Monday | E1: Tuesday | F1: Wednesday | G1: Thrusday | H1: Friday | I1: Saturday | J1: Legajo | K1: CCMSID | L1: Legajo Telecom | M1: LOB
A2: ='Sups'' Final Roster 0913-0919'!A2 -> Campero Juarez Maria Guadalupe | B2: ='Sups'' Final Roster 0913-0919'!B2 -> Arias Juan José
A3: ='Sups'' Final Roster 0913-0919'!A3 -> Campero Juarez Maria Guadalupe | B3: ='Sups'' Final Roster 0913-0919'!B3 -> Corbera Susana Sofía
A4: ='Sups'' Final Roster 0913-0919'!A4 -> Campero Juarez Maria Guadalupe | B4: ='Sups'' Final Roster 0913-0919'!B4 -> Podazza Villagra Daniel Matias
A5: ='Sups'' Final Roster 0913-0919'!A5 -> Campero Juarez Maria Guadalupe | B5: ='Sups'' Final Roster 0913-0919'!B5 -> Gregoratti Juan Carlos
A6: ='Sups'' Final Roster 0913-0919'!A6 -> Pérez Zitzke Agustina | B6: ='Sups'' Final Roster 0913-0919'!B6 -> Vazquez Valladares Eduardo Alejandro
A7: ='Sups'' Final Roster 0913-0919'!A7 -> Pérez Zitzke Agustina | B7: ='Sups'' Final Roster 0913-0919'!B7 -> Ramallo Jose Emanuel
A8: ='Sups'' Final Roster 0913-0919'!A8 -> Campero Juarez Maria Guadalupe | B8: ='Sups'' Final Roster 0913-0919'!B8 -> Criado Esteban
A9: ='Sups'' Final Roster 0913-0919'!A10 -> Pérez Zitzke Agustina | B9: ='Sups'' Final Roster 0913-0919'!B10 -> Villa Aleman Alejandro Roberto
A10: ='Sups'' Final Roster 0913-0919'!A11 -> Ortiz Jose María | B10: ='Sups'' Final Roster 0913-0919'!B11 -> Brandan Ernesto Alejandro
A11: ='Sups'' Final Roster 0913-0919'!A12 -> Ortiz Jose María | B11: ='Sups'' Final Roster 0913-0919'!B12 -> Britos Fernando José
A12: ='Sups'' Final Roster 0913-0919'!#REF! -> #REF! | B12: ='Sups'' Final Roster 0913-0919'!#REF! -> #REF!
A13: ='Sups'' Final Roster 0913-0919'!#REF! -> #REF! | B13: ='Sups'' Final Roster 0913-0919'!#REF! -> #REF!
A14: ='Sups'' Final Roster 0913-0919'!#REF! -> #REF! | B14: ='Sups'' Final Roster 0913-0919'!#REF! -> #REF!
A15: ='Sups'' Final Roster 0913-0919'!#REF! -> #REF! | B15: ='Sups'' Final Roster 0913-0919'!#REF! -> #REF!
A16: ='Sups'' Final Roster 0913-0919'!#REF! -> #REF! | B16: ='Sups'' Final Roster 0913-0919'!#REF! -> #REF!
A17: ='Sups'' Final Roster 0913-0919'!#REF! -> #REF! | B17: ='Sups'' Final Roster 0913-0919'!#REF! -> #REF!
A18: ='Sups'' Final Roster 0913-0919'!#REF! -> #REF! | B18: ='Sups'' Final Roster 0913-0919'!#REF! -> #REF!
A19: ='Sups'' Final Roster 0913-0919'!#REF! -> #REF! | B19: ='Sups'' Final Roster 0913-0919'!#REF! -> #REF!
A20: ='Sups'' Final Roster 0913-0919'!#REF! -> #REF! | B20: ='Sups'' Final Roster 0913-0919'!#REF! -> #REF!
A21: ='Sups'' Final Roster 0913-0919'!#REF! -> #REF! | B21: ='Sups'' Final Roster 0913-0919'!#REF! -> #REF!
A22: ='Sups'' Final Roster 0913-0919'!#REF! -> #REF! | B22: ='Sups'' Final Roster 0913-0919'!#REF! -> #REF!
A23: ='Sups'' Final Roster 0913-0919'!#REF! -> #REF! | B23: ='Sups'' Final Roster 0913-0919'!#REF! -> #REF!
A24: ='Sups'' Final Roster 0913-0919'!A13 -> Ortiz Jose María | B24: ='Sups'' Final Roster 0913-0919'!B13 -> Esquivel Pavan Pamela Sol
A25: ='Sups'' Final Roster 0913-0919'!A14 -> Ortiz Jose María | B25: ='Sups'' Final Roster 0913-0919'!B14 -> Gerez Andrea Soledad
A26: ='Sups'' Final Roster 0913-0919'!#REF! -> #REF! | B26: ='Sups'' Final Roster 0913-0919'!#REF! -> #REF!
A27: ='Sups'' Final Roster 0913-0919'!#REF! -> #REF! | B27: ='Sups'' Final Roster 0913-0919'!#REF! -> #REF!
A28: ='Sups'' Final Roster 0913-0919'!#REF! -> #REF! | B28: ='Sups'' Final Roster 0913-0919'!#REF! -> #REF!
A29: ='Sups'' Final Roster 0913-0919'!#REF! -> #REF! | B29: ='Sups'' Final Roster 0913-0919'!#REF! -> #REF!
A30: ='Sups'' Final Roster 0913-0919'!#REF! -> #REF! | B30: ='Sups'' Final Roster 0913-0919'!#REF! -> #REF!
A31: ='Sups'' Final Roster 0913-0919'!#REF! -> #REF! | B31: ='Sups'' Final Roster 0913-0919'!#REF! -> #REF!
A32: ='Sups'' Final Roster 0913-0919'!#REF! -> #REF! | B32: ='Sups'' Final Roster 0913-0919'!#REF! -> #REF!
A33: ='Sups'' Final Roster 0913-0919'!#REF! -> #REF! | B33: ='Sups'' Final Roster 0913-0919'!#REF! -> #REF!
A34: ='Sups'' Final Roster 0913-0919'!#REF! -> #REF! | B34: ='Sups'' Final Roster 0913-0919'!#REF! -> #REF!
A35: ='Sups'' Final Roster 0913-0919'!#REF! -> #REF! | B35: ='Sups'' Final Roster 0913-0919'!#REF! -> #REF!
A36: ='Sups'' Final Roster 0913-0919'!#REF! -> #REF! | B36: ='Sups'' Final Roster 0913-0919'!#REF! -> #REF!
A37: ='Sups'' Final Roster 0913-0919'!#REF! -> #REF! | B37: ='Sups'' Final Roster 0913-0919'!#REF! -> #REF!
... A43: ='Sups'' Final Roster 0913-0919'!#REF! -> #REF! | B43: ='Sups'' Final Roster 0913-0919'!#REF! -> #REF!
A44: ='Sups'' Final Roster 0913-0919'!A15 -> Pérez Zitzke Agustina | B44: ='Sups'' Final Roster 0913-0919'!B15 -> Grimaldi Agustina Sofía
A45: ='Sups'' Final Roster 0913-0919'!A16 -> Pérez Zitzke Agustina | B45: ='Sups'' Final Roster 0913-0919'!B16 -> Palomino Juan Pablo
...

Sheet Resumen
G1: h
B2: Lob | C2: Nomina | D2: LOAs | E2: %
B3: Front | C3: =+COUNTIF(Agents!$Z$2:$Z$149,Resumen!B3) -> 0 | D3: =+SUMIF(Agents!$Z$2:$Z$149,Resumen!B3,Agents!$AP$2:$AP$149) -> 0 | E3: =D3/C3 -> #DIV/0!
B4: Retención Móvil | C4: =+COUNTIF(Agents!$Z$2:$Z$149,Resumen!B4) -> 0 | D4: =+SUMIF(Agents!$Z$2:$Z$149,Resumen!B4,Agents!$AP$2:$AP$149) -> 0 | E4: =D4/C4 -> #DIV/0!
B5: Downselling | C5: =+COUNTIF(Agents!$Z$2:$Z$149,Resumen!B5) -> 0 | D5: =+SUMIF(Agents!$Z$2:$Z$149,Resumen!B5,Agents!$AP$2:$AP$149) -> 0 | E5: =D5/C5 -> #DIV/0!
B6: Retención Red Preferida | C6: =+COUNTIF(Agents!$Z$2:$Z$149,Resumen!B6) -> 0 | D6: =+SUMIF(Agents!$Z$2:$Z$149,Resumen!B6,Agents!$AP$2:$AP$149) -> 0 | E6: =D6/C6 -> #DIV/0!
B7: Total | C7: =SUM(C3:C6) -> 0 | D7: =SUM(D3:D6) -> 0 | E7: =D7/C7 -> #DIV/0!
B9: Front
C11: Sunday | D11: Monday | E11: Tuesday | F11: Wednesday | G11: Thrusday | H11: Friday | I11: Saturday
B12: HC Total Inbound | C12: 0 | D12: =+C12 -> 0 | E12: =+D12 -> 0 | F12: =+E12 -> 0 | G12: =+F12 -> 0 | H12: =+G12 -> 0 | I12: =+H12 -> 0
B13: Approved OFF | C13: =+COUNTIFS(Agents!E$2:E$149,Resumen!$B13,Agents!$Z$2:$Z$149,Resumen!$B$3) -> 0 | D13: =+COUNTIFS(Agents!F$2:F$149,Resumen!$B13,Agents!$Z$2:$Z$149,Resumen!$B$3) -> 0 | E13: =+COUNTIFS(Agents!G$2:G$149,Resumen!$B13,Agents!$Z$2:$Z$149,Resumen!$B$3) -> 0 | F13: =+COUNTIFS(Agents!H$2:H$149,Resumen!$B13,Agents!$Z$2:$Z$149,Resumen!$B$3) -> 0 | G13: =+COUNTIFS(Agents!I$2:I$149,Resumen!$B13,Agents!$Z$2:$Z$149,Resumen!$B$3) -> 0 | H13: =+COUNTIFS(Agents!J$2:J$149,Resumen!$B13,Agents!$Z$2:$Z$149,Resumen!$B$3) -> 0 | I13: =+COUNTIFS(Agents!K$2:K$149,Resumen!$B13,Agents!$Z$2:$Z$149,Resumen!$B$3) -> 0
B14: LOA | C14: =+COUNTIFS(Agents!E$2:E$149,Resumen!$B14,Agents!$Z$2:$Z$149,Resumen!$B$3) -> 0 | D14: =+COUNTIFS(Agents!F$2:F$149,Resumen!$B14,Agents!$Z$2:$Z$149,Resumen!$B$3) -> 0 | E14: =+COUNTIFS(Agents!G$2:G$149,Resumen!$B14,Agents!$Z$2:$Z$149,Resumen!$B$3) -> 0 | F14: =+COUNTIFS(Agents!H$2:H$149,Resumen!$B14,Agents!$Z$2:$Z$149,Resumen!$B$3) -> 0 | G14: =+COUNTIFS(Agents!I$2:I$149,Resumen!$B14,Agents!$Z$2:$Z$149,Resumen!$B$3) -> 0 | H14: =+COUNTIFS(Agents!J$2:J$149,Resumen!$B14,Agents!$Z$2:$Z$149,Resumen!$B$3) -> 0 | I14: 0
B15: OFF | C15: =+COUNTIFS(Agents!E$2:E$149,Resumen!$B15,Agents!$Z$2:$Z$149,Resumen!$B$3) -> 0 | D15: =+COUNTIFS(Agents!F$2:F$149,Resumen!$B15,Agents!$Z$2:$Z$149,Resumen!$B$3) -> 0 | E15: =+COUNTIFS(Agents!G$2:G$149,Resumen!$B15,Agents!$Z$2:$Z$149,Resumen!$B$3) -> 0 | F15: =+COUNTIFS(Agents!H$2:H$149,Resumen!$B15,Agents!$Z$2:$Z$149,Resumen!$B$3) -> 0 | G15: 0 | H15: =+COUNTIFS(Agents!J$2:J$149,Resumen!$B15,Agents!$Z$2:$Z$149,Resumen!$B$3) -> 0 | I15: =+COUNTIFS(Agents!K$2:K$149,Resumen!$B15,Agents!$Z$2:$Z$149,Resumen!$B$3) -> 0
B16: Study Day | C16: =+COUNTIFS(Agents!E$2:E$149,Resumen!$B16,Agents!$Z$2:$Z$149,Resumen!$B$3) -> 0 | D16: =+COUNTIFS(Agents!F$2:F$149,Resumen!$B16,Agents!$Z$2:$Z$149,Resumen!$B$3) -> 0 | E16: =+COUNTIFS(Agents!G$2:G$149,Resumen!$B16,Agents!$Z$2:$Z$149,Resumen!$B$3) -> 0 | F16: =+COUNTIFS(Agents!H$2:H$149,Resumen!$B16,Agents!$Z$2:$Z$149,Resumen!$B$3) -> 0 | G16: =+COUNTIFS(Agents!I$2:I$149,Resumen!$B16,Agents!$Z$2:$Z$149,Resumen!$B$3) -> 0 | H16: =+COUNTIFS(Agents!J$2:J$149,Resumen!$B16,Agents!$Z$2:$Z$149,Resumen!$B$3) -> 0 | I16: =+COUNTIFS(Agents!K$2:K$149,Resumen!$B16,Agents!$Z$2:$Z$149,Resumen!$B$3) -> 0
B17: VAC | C17: =+COUNTIFS(Agents!E$2:E$149,Resumen!$B17,Agents!$Z$2:$Z$149,Resumen!$B$3) -> 0 | D17: =+COUNTIFS(Agents!F$2:F$149,Resumen!$B17,Agents!$Z$2:$Z$149,Resumen!$B$3) -> 0 | E17: =+COUNTIFS(Agents!G$2:G$149,Resumen!$B17,Agents!$Z$2:$Z$149,Resumen!$B$3) -> 0 | F17: =+COUNTIFS(Agents!H$2:H$149,Resumen!$B17,Agents!$Z$2:$Z$149,Resumen!$B$3) -> 0 | G17: =+COUNTIFS(Agents!I$2:I$149,Resumen!$B17,Agents!$Z$2:$Z$149,Resumen!$B$3) -> 0 | H17: =+COUNTIFS(Agents!J$2:J$149,Resumen!$B17,Agents!$Z$2:$Z$149,Resumen!$B$3) -> 0 | I17: =+COUNTIFS(Agents!K$2:K$149,Resumen!$B17,Agents!$Z$2:$Z$149,Resumen!$B$3) -> 0
B18: SUS | C18: =+COUNTIFS(Agents!E$2:E$149,Resumen!$B18,Agents!$Z$2:$Z$149,Resumen!$B$3) -> 0 | D18: =+COUNTIFS(Agents!F$2:F$149,Resumen!$B18,Agents!$Z$2:$Z$149,Resumen!$B$3) -> 0 | E18: =+COUNTIFS(Agents!G$2:G$149,Resumen!$B18,Agents!$Z$2:$Z$149,Resumen!$B$3) -> 0 | F18: =+COUNTIFS(Agents!H$2:H$149,Resumen!$B18,Agents!$Z$2:$Z$149,Resumen!$B$3) -> 0 | G18: =+COUNTIFS(Agents!I$2:I$149,Resumen!$B18,Agents!$Z$2:$Z$149,Resumen!$B$3) -> 0 | H18: =+COUNTIFS(Agents!J$2:J$149,Resumen!$B18,Agents!$Z$2:$Z$149,Resumen!$B$3) -> 0 | I18: =+COUNTIFS(Agents!K$2:K$149,Resumen!$B18,Agents!$Z$2:$Z$149,Resumen!$B$3) -> 0
B19: HC Bis | C19: =+C12-SUM(C13:C18) -> 0 | D19: =+D12-SUM(D13:D18) -> 0 | E19: =+E12-SUM(E13:E18) -> 0 | F19: =+F12-SUM(F13:F18) -> 0 | G19: =+G12-SUM(G13:G18) -> 0 | H19: =+H12-SUM(H13:H18) -> 0 | I19: =+I12-SUM(I13:I18) -> 0
B20: HC Total Inbound Neto | C20: =+C12-C15-C13 -> 0 | D20: =+D12-D15-D13 -> 0 | E20: =+E12-E15-E13 -> 0 | F20: =+F12-F15-F13 -> 0 | G20: =+G12-G15-G13 -> 0 | H20: =+H12-H15-H13 -> 0 | I20: =+I12-I15-I13 -> 0
C22: =+C11 -> Sunday | D22: =+D11 -> Monday | E22: =+E11 -> Tuesday | F22: =+F11 -> Wednesday | G22: =+G11 -> Thrusday | H22: =+H11 -> Friday | I22: =+I11 -> Saturday
B23: Hs, Total Inbound | C23: =+SUMIF(Agents!$Z$2:$Z$149,Resumen!$B$3,Agents!O$2:O$149) -> 0 | D23: =+SUMIF(Agents!$Z$2:$Z$149,Resumen!$B$3,Agents!P$2:P$149) -> 0 | E23: =+SUMIF(Agents!$Z$2:$Z$149,Resumen!$B$3,Agents!Q$2:Q$149) -> 0 | F23: =+SUMIF(Agents!$Z$2:$Z$149,Resumen!$B$3,Agents!R$2:R$149) -> 0 | G23: =+SUMIF(Agents!$Z$2:$Z$149,Resumen!$B$3,Agents!S$2:S$149) -> 0 | H23: =+SUMIF(Agents!$Z$2:$Z$149,Resumen!$B$3,Agents!T$2:T$149) -> 0 | I23: =+SUMIF(Agents!$Z$2:$Z$149,Resumen!$B$3,Agents!U$2:U$149) -> 0
B24: Shift Avg. | C24: =IFERROR(C23/C19,0) -> 0 | D24: =IFERROR(D23/D19,0) -> 0 | E24: =IFERROR(E23/E19,0) -> 0 | F24: =IFERROR(F23/F19,0) -> 0 | G24: =IFERROR(G23/G19,0) -> 0 | H24: =IFERROR(H23/H19,0) -> 0 | I24: =IFERROR(I23/I19,0) -> 0
B26: Retención Móvil
C28: Sunday | D28: Monday | E28: Tuesday | F28: Wednesday | G28: Thrusday | H28: Friday | I28: Saturday
B29: HC Total Inbound | C29: =+COUNTIF(Agents!$Z$2:$Z$149,Resumen!B4) -> 0 | D29: =+C29 -> 0 | E29: =+D29 -> 0 | F29: =+E29 -> 0 | G29: =+F29 -> 0 | H29: =+G29 -> 0 | I29: =+H29 -> 0
B30: Approved OFF | C30: =+COUNTIFS(Agents!E$2:E$149,Resumen!$B30,Agents!$Z$2:$Z$149,Resumen!$B$4) -> 0 | D30: =+COUNTIFS(Agents!F$2:F$149,Resumen!$B30,Agents!$Z$2:$Z$149,Resumen!$B$4) -> 0 | E30: =+COUNTIFS(Agents!G$2:G$149,Resumen!$B30,Agents!$Z$2:$Z$149,Resumen!$B$4) -> 0 | F30: =+COUNTIFS(Agents!H$2:H$149,Resumen!$B30,Agents!$Z$2:$Z$149,Resumen!$B$4) -> 0 | G30: =+COUNTIFS(Agents!I$2:I$149,Resumen!$B30,Agents!$Z$2:$Z$149,Resumen!$B$4) -> 0 | H30: =+COUNTIFS(Agents!J$2:J$149,Resumen!$B30,Agents!$Z$2:$Z$149,Resumen!$B$4) -> 0 | I30: =+COUNTIFS(Agents!K$2:K$149,Resumen!$B30,Agents!$Z$2:$Z$149,Resumen!$B$4) -> 0
B31: LOA | C31: =+COUNTIFS(Agents!E$2:E$149,Resumen!$B31,Agents!$Z$2:$Z$149,Resumen!$B$4) -> 0 | D31: =+COUNTIFS(Agents!F$2:F$149,Resumen!$B31,Agents!$Z$2:$Z$149,Resumen!$B$4) -> 0 | E31: =+COUNTIFS(Agents!G$2:G$149,Resumen!$B31,Agents!$Z$2:$Z$149,Resumen!$B$4) -> 0 | F31: =+COUNTIFS(Agents!H$2:H$149,Resumen!$B31,Agents!$Z$2:$Z$149,Resumen!$B$4) -> 0 | G31: =+COUNTIFS(Agents!I$2:I$149,Resumen!$B31,Agents!$Z$2:$Z$149,Resumen!$B$4) -> 0 | H31: =+COUNTIFS(Agents!J$2:J$149,Resumen!$B31,Agents!$Z$2:$Z$149,Resumen!$B$4) -> 0 | I31: =+COUNTIFS(Agents!K$2:K$149,Resumen!$B31,Agents!$Z$2:$Z$149,Resumen!$B$4) -> 0
B32: OFF | C32: =+COUNTIFS(Agents!E$2:E$149,Resumen!$B32,Agents!$Z$2:$Z$149,Resumen!$B$4) -> 0 | D32: =+COUNTIFS(Agents!F$2:F$149,Resumen!$B32,Agents!$Z$2:$Z$149,Resumen!$B$4) -> 0 | E32: =+COUNTIFS(Agents!G$2:G$149,Resumen!$B32,Agents!$Z$2:$Z$149,Resumen!$B$4) -> 0 | F32: =+COUNTIFS(Agents!H$2:H$149,Resumen!$B32,Agents!$Z$2:$Z$149,Resumen!$B$4) -> 0 | G32: =+COUNTIFS(Agents!I$2:I$149,Resumen!$B32,Agents!$Z$2:$Z$149,Resumen!$B$4) -> 0 | H32: =+COUNTIFS(Agents!J$2:J$149,Resumen!$B32,Agents!$Z$2:$Z$149,Resumen!$B$4) -> 0 | I32: =+COUNTIFS(Agents!K$2:K$149,Resumen!$B32,Agents!$Z$2:$Z$149,Resumen!$B$4) -> 0
B33: Study Day | C33: =+COUNTIFS(Agents!E$2:E$149,Resumen!$B33,Agents!$Z$2:$Z$149,Resumen!$B$4) -> 0 | D33: =+COUNTIFS(Agents!F$2:F$149,Resumen!$B33,Agents!$Z$2:$Z$149,Resumen!$B$4) -> 0 | E33: =+COUNTIFS(Agents!G$2:G$149,Resumen!$B33,Agents!$Z$2:$Z$149,Resumen!$B$4) -> 0 | F33: =+COUNTIFS(Agents!H$2:H$149,Resumen!$B33,Agents!$Z$2:$Z$149,Resumen!$B$4) -> 0 | G33: =+COUNTIFS(Agents!I$2:I$149,Resumen!$B33,Agents!$Z$2:$Z$149,Resumen!$B$4) -> 0 | H33: =+COUNTIFS(Agents!J$2:J$149,Resumen!$B33,Agents!$Z$2:$Z$149,Resumen!$B$4) -> 0 | I33: =+COUNTIFS(Agents!K$2:K$149,Resumen!$B33,Agents!$Z$2:$Z$149,Resumen!$B$4) -> 0
B34: VAC | C34: =+COUNTIFS(Agents!E$2:E$149,Resumen!$B34,Agents!$Z$2:$Z$149,Resumen!$B$4) -> 0 | D34: =+COUNTIFS(Agents!F$2:F$149,Resumen!$B34,Agents!$Z$2:$Z$149,Resumen!$B$4) -> 0 | E34: =+COUNTIFS(Agents!G$2:G$149,Resumen!$B34,Agents!$Z$2:$Z$149,Resumen!$B$4) -> 0 | F34: =+COUNTIFS(Agents!H$2:H$149,Resumen!$B34,Agents!$Z$2:$Z$149,Resumen!$B$4) -> 0 | G34: =+COUNTIFS(Agents!I$2:I$149,Resumen!$B34,Agents!$Z$2:$Z$149,Resumen!$B$4) -> 0 | H34: =+COUNTIFS(Agents!J$2:J$149,Resumen!$B34,Agents!$Z$2:$Z$149,Resumen!$B$4) -> 0 | I34: =+COUNTIFS(Agents!K$2:K$149,Resumen!$B34,Agents!$Z$2:$Z$149,Resumen!$B$4) -> 0
B35: SUS | C35: =+COUNTIFS(Agents!E$2:E$149,Resumen!$B35,Agents!$Z$2:$Z$149,Resumen!$B$4) -> 0 | D35: =+COUNTIFS(Agents!F$2:F$149,Resumen!$B35,Agents!$Z$2:$Z$149,Resumen!$B$4) -> 0 | E35: =+COUNTIFS(Agents!G$2:G$149,Resumen!$B35,Agents!$Z$2:$Z$149,Resumen!$B$4) -> 0 | F35: =+COUNTIFS(Agents!H$2:H$149,Resumen!$B35,Agents!$Z$2:$Z$149,Resumen!$B$4) -> 0 | G35: =+COUNTIFS(Agents!I$2:I$149,Resumen!$B35,Agents!$Z$2:$Z$149,Resumen!$B$4) -> 0 | H35: =+COUNTIFS(Agents!J$2:J$149,Resumen!$B35,Agents!$Z$2:$Z$149,Resumen!$B$4) -> 0 | I35: =+COUNTIFS(Agents!K$2:K$149,Resumen!$B35,Agents!$Z$2:$Z$149,Resumen!$B$4) -> 0
B36: HC Bis | C36: =+C29-SUM(C30:C35) -> 0 | D36: =+D29-SUM(D30:D35) -> 0 | E36: =+E29-SUM(E30:E35) -> 0 | F36: =+F29-SUM(F30:F35) -> 0 | G36: =+G29-SUM(G30:G35) -> 0 | H36: =+H29-SUM(H30:H35) -> 0 | I36: =+I29-SUM(I30:I35) -> 0
B37: HC Total Inbound Neto | C37: =+C29-C32-C30 -> 0 | D37: =+D29-D32-D30 -> 0 | E37: =+E29-E32-E30 -> 0 | F37: =+F29-F32-F30 -> 0 | G37: =+G29-G32-G30 -> 0 | H37: =+H29-H32-H30 -> 0 | I37: =+I29-I32-I30 -> 0
C39: =+C28 -> Sunday | D39: =+D28 -> Monday | E39: =+E28 -> Tuesday | F39: =+F28 -> Wednesday | G39: =+G28 -> Thrusday | H39: =+H28 -> Friday | I39: =+I28 -> Saturday
B40: Hs, Total Inbound | C40: =+SUMIF(Agents!$Z$2:$Z$149,Resumen!$B$4,Agents!O$2:O$149) -> 0 | D40: =+SUMIF(Agents!$Z$2:$Z$149,Resumen!$B$4,Agents!P$2:P$149) -> 0 | E40: =+SUMIF(Agents!$Z$2:$Z$149,Resumen!$B$4,Agents!Q$2:Q$149) -> 0 | F40: =+SUMIF(Agents!$Z$2:$Z$149,Resumen!$B$4,Agents!R$2:R$149) -> 0 | G40: =+SUMIF(Agents!$Z$2:$Z$149,Resumen!$B$4,Agents!S$2:S$149) -> 0 | H40: =+SUMIF(Agents!$Z$2:$Z$149,Resumen!$B$4,Agents!T$2:T$149) -> 0 | I40: =+SUMIF(Agents!$Z$2:$Z$149,Resumen!$B$4,Agents!U$2:U$149) -> 0
B41: Shift Avg. | C41: =IFERROR(C40/C36,0) -> 0 | D41: =IFERROR(D40/D36,0) -> 0 | E41: =IFERROR(E40/E36,0) -> 0 | F41: =IFERROR(F40/F36,0) -> 0 | G41: =IFERROR(G40/G36,0) -> 0 | H41: =IFERROR(H40/H36,0) -> 0 | I41: =IFERROR(I40/I36,0) -> 0
B43: Downselling
C45: Sunday | D45: Monday | E45: Tuesday | F45: Wednesday | G45: Thrusday | H45: Friday | I45: Saturday
B46: HC Total Inbound | C46: =+COUNTIF(Agents!$Z$2:$Z$149,Resumen!B5) -> 0 | D46: =+C46 -> 0 | E46: =+D46 -> 0 | F46: =+E46 -> 0 | G46: =+F46 -> 0 | H46: =+G46 -> 0 | I46: =+H46 -> 0
B47: Approved OFF | C47: =+COUNTIFS(Agents!E$2:E$149,Resumen!$B47,Agents!$Z$2:$Z$149,Resumen!$B$5) -> 0 | D47: =+COUNTIFS(Agents!F$2:F$149,Resumen!$B47,Agents!$Z$2:$Z$149,Resumen!$B$5) -> 0 | E47: =+COUNTIFS(Agents!G$2:G$149,Resumen!$B47,Agents!$Z$2:$Z$149,Resumen!$B$5) -> 0 | F47: =+COUNTIFS(Agents!H$2:H$149,Resumen!$B47,Agents!$Z$2:$Z$149,Resumen!$B$5) -> 0 | G47: =+COUNTIFS(Agents!I$2:I$149,Resumen!$B47,Agents!$Z$2:$Z$149,Resumen!$B$5) -> 0 | H47: =+COUNTIFS(Agents!J$2:J$149,Resumen!$B47,Agents!$Z$2:$Z$149,Resumen!$B$5) -> 0 | I47: =+COUNTIFS(Agents!K$2:K$149,Resumen!$B47,Agents!$Z$2:$Z$149,Resumen!$B$5) -> 0
B48: LOA | C48: =+COUNTIFS(Agents!E$2:E$149,Resumen!$B48,Agents!$Z$2:$Z$149,Resumen!$B$5) -> 0 | D48: =+COUNTIFS(Agents!F$2:F$149,Resumen!$B48,Agents!$Z$2:$Z$149,Resumen!$B$5) -> 0 | E48: =+COUNTIFS(Agents!G$2:G$149,Resumen!$B48,Agents!$Z$2:$Z$149,Resumen!$B$5) -> 0 | F48: =+COUNTIFS(Agents!H$2:H$149,Resumen!$B48,Agents!$Z$2:$Z$149,Resumen!$B$5) -> 0 | G48: =+COUNTIFS(Agents!I$2:I$149,Resumen!$B48,Agents!$Z$2:$Z$149,Resumen!$B$5) -> 0 | H48: =+COUNTIFS(Agents!J$2:J$149,Resumen!$B48,Agents!$Z$2:$Z$149,Resumen!$B$5) -> 0 | I48: =+COUNTIFS(Agents!K$2:K$149,Resumen!$B48,Agents!$Z$2:$Z$149,Resumen!$B$5) -> 0
...
